ERROR 2019-07-04 03:13:55,654 - Function: compare_image, args: ('smurfscreen.png', 'buff.png'), kwargs {}, Result: OpenCV(4.0.1) C:\projects\opencv-python\opencv\modules\imgproc\src\color.cpp:181: error: (-215:Assertion failed) !_src.empty() in function 'cv::cvtColor'

ERROR 2019-07-04 16:32:47,820 - Function: screen, args: (<adb.device.Device object at 0x000001ED0FDA0710>, 'smurfscreen.png'), kwargs {}, Result: bytearray index out of range
ERROR 2019-07-04 16:32:47,897 - Attempting a reconnect in 0.38s
Traceback (most recent call last):
  File "C:\Program Files\Python36\lib\site-packages\discord\gateway.py", line 464, in poll_event
    msg = await self.recv()
  File "C:\Program Files\Python36\lib\site-packages\websockets\protocol.py", line 350, in recv
    yield from self.ensure_open()
  File "C:\Program Files\Python36\lib\site-packages\websockets\protocol.py", line 501, in ensure_open
    self.close_code, self.close_reason) from self.transfer_data_exc
websockets.exceptions.ConnectionClosed: WebSocket connection is closed: code = 1000 (OK), no reason

The above exception was the direct cause of the following exception:

Traceback (most recent call last):
  File "C:\Program Files\Python36\lib\site-packages\discord\client.py", line 393, in connect
    await self._connect()
  File "C:\Program Files\Python36\lib\site-packages\discord\client.py", line 358, in _connect
    await self.ws.poll_event()
  File "C:\Program Files\Python36\lib\site-packages\discord\gateway.py", line 472, in poll_event
    raise ConnectionClosed(exc, shard_id=self.shard_id) from exc
discord.errors.ConnectionClosed: WebSocket connection is closed: code = 1000 (OK), no reason
ERROR 2019-07-04 16:32:57,874 - Function: screen, args: (<adb.device.Device object at 0x000001ED0FDA0710>, 'smurfscreen.png'), kwargs {}, Result: ERROR: 'FAIL' 0022device '127.0.0.1:62025' not found
ERROR 2019-07-05 14:40:11,268 - Function: screen, args: (<adb.device.Device object at 0x000001ED0FDA0710>, 'smurfscreen.png'), kwargs {}, Result: ERROR: 'FAIL' 0022device '127.0.0.1:62025' not found
ERROR 2019-07-11 15:14:52,333 - Function: screen, args: (<adb.device.Device object at 0x00000226E9DA0668>, 'smurfscreen.png'), kwargs {}, Result: bytearray index out of range
ERROR 2019-07-11 15:14:52,429 - Attempting a reconnect in 0.37s
Traceback (most recent call last):
  File "C:\Program Files\Python36\lib\site-packages\discord\gateway.py", line 464, in poll_event
    msg = await self.recv()
  File "C:\Program Files\Python36\lib\site-packages\websockets\protocol.py", line 350, in recv
    yield from self.ensure_open()
  File "C:\Program Files\Python36\lib\site-packages\websockets\protocol.py", line 501, in ensure_open
    self.close_code, self.close_reason) from self.transfer_data_exc
websockets.exceptions.ConnectionClosed: WebSocket connection is closed: code = 1000 (OK), no reason

The above exception was the direct cause of the following exception:

Traceback (most recent call last):
  File "C:\Program Files\Python36\lib\site-packages\discord\client.py", line 393, in connect
    await self._connect()
  File "C:\Program Files\Python36\lib\site-packages\discord\client.py", line 358, in _connect
    await self.ws.poll_event()
  File "C:\Program Files\Python36\lib\site-packages\discord\gateway.py", line 472, in poll_event
    raise ConnectionClosed(exc, shard_id=self.shard_id) from exc
discord.errors.ConnectionClosed: WebSocket connection is closed: code = 1000 (OK), no reason
ERROR 2019-07-11 15:15:02,401 - Function: screen, args: (<adb.device.Device object at 0x00000226E9DA0668>, 'smurfscreen.png'), kwargs {}, Result: ERROR: 'FAIL' 0022device '127.0.0.1:62025' not found
ERROR 2019-07-11 22:54:18,200 - Task exception was never retrieved
future: <Task finished coro=<check_titan() done, defined at D:/MSL_Python/main.py:650> exception=HTTPException('SERVICE UNAVAILABLE (status code: 503): This resource is currently overloaded, and thus too busy to serve requests',)>
Traceback (most recent call last):
  File "D:/MSL_Python/main.py", line 681, in check_titan
    async for msg in channel.history(limit=20):
  File "C:\Program Files\Python36\lib\site-packages\discord\iterators.py", line 84, in __anext__
    msg = await self.next()
  File "C:\Program Files\Python36\lib\site-packages\discord\iterators.py", line 263, in next
    await self.fill_messages()
  File "C:\Program Files\Python36\lib\site-packages\discord\iterators.py", line 309, in fill_messages
    data = await self._retrieve_messages(self.retrieve)
  File "C:\Program Files\Python36\lib\site-packages\discord\iterators.py", line 329, in _retrieve_messages_before_strategy
    data = await self.logs_from(self.channel.id, retrieve, before=before)
  File "C:\Program Files\Python36\lib\site-packages\discord\http.py", line 222, in request
    raise HTTPException(r, data)
discord.errors.HTTPException: SERVICE UNAVAILABLE (status code: 503): This resource is currently overloaded, and thus too busy to serve requests
ERROR 2019-07-13 16:34:16,510 - Function: screen, args: (<adb.device.Device object at 0x0000027868D11668>, 'smurfscreen.png'), kwargs {}, Result: bytearray index out of range
ERROR 2019-07-13 16:34:16,589 - Attempting a reconnect in 0.04s
Traceback (most recent call last):
  File "C:\Program Files\Python36\lib\site-packages\discord\gateway.py", line 464, in poll_event
    msg = await self.recv()
  File "C:\Program Files\Python36\lib\site-packages\websockets\protocol.py", line 350, in recv
    yield from self.ensure_open()
  File "C:\Program Files\Python36\lib\site-packages\websockets\protocol.py", line 501, in ensure_open
    self.close_code, self.close_reason) from self.transfer_data_exc
websockets.exceptions.ConnectionClosed: WebSocket connection is closed: code = 1000 (OK), no reason

The above exception was the direct cause of the following exception:

Traceback (most recent call last):
  File "C:\Program Files\Python36\lib\site-packages\discord\client.py", line 393, in connect
    await self._connect()
  File "C:\Program Files\Python36\lib\site-packages\discord\client.py", line 358, in _connect
    await self.ws.poll_event()
  File "C:\Program Files\Python36\lib\site-packages\discord\gateway.py", line 472, in poll_event
    raise ConnectionClosed(exc, shard_id=self.shard_id) from exc
discord.errors.ConnectionClosed: WebSocket connection is closed: code = 1000 (OK), no reason
ERROR 2019-07-13 16:34:26,558 - Function: screen, args: (<adb.device.Device object at 0x0000027868D11668>, 'smurfscreen.png'), kwargs {}, Result: ERROR: 'FAIL' 0022device '127.0.0.1:62025' not found
ERROR 2019-07-14 08:16:38,490 - Function: screen, args: (<adb.device.Device object at 0x0000027868D11668>, 'smurfscreen.png'), kwargs {}, Result: bytearray index out of range
ERROR 2019-07-14 08:16:48,512 - Function: screen, args: (<adb.device.Device object at 0x0000027868D11668>, 'smurfscreen.png'), kwargs {}, Result: ERROR: 'FAIL' 0022device '127.0.0.1:62025' not found
ERROR 2019-07-14 11:55:53,433 - Function: screen, args: (<adb.device.Device object at 0x0000027868D11668>, 'smurfscreen.png'), kwargs {}, Result: ERROR: 'FAIL' 0022device '127.0.0.1:62025' not found
ERROR 2019-07-16 10:16:26,290 - Function: screen, args: (<adb.device.Device object at 0x000001ABC6560668>, 'smurfscreen.png'), kwargs {}, Result: bytearray index out of range
ERROR 2019-07-16 10:16:26,373 - Attempting a reconnect in 0.75s
Traceback (most recent call last):
  File "C:\Program Files\Python36\lib\site-packages\discord\gateway.py", line 464, in poll_event
    msg = await self.recv()
  File "C:\Program Files\Python36\lib\site-packages\websockets\protocol.py", line 350, in recv
    yield from self.ensure_open()
  File "C:\Program Files\Python36\lib\site-packages\websockets\protocol.py", line 501, in ensure_open
    self.close_code, self.close_reason) from self.transfer_data_exc
websockets.exceptions.ConnectionClosed: WebSocket connection is closed: code = 1000 (OK), no reason

The above exception was the direct cause of the following exception:

Traceback (most recent call last):
  File "C:\Program Files\Python36\lib\site-packages\discord\client.py", line 393, in connect
    await self._connect()
  File "C:\Program Files\Python36\lib\site-packages\discord\client.py", line 358, in _connect
    await self.ws.poll_event()
  File "C:\Program Files\Python36\lib\site-packages\discord\gateway.py", line 472, in poll_event
    raise ConnectionClosed(exc, shard_id=self.shard_id) from exc
discord.errors.ConnectionClosed: WebSocket connection is closed: code = 1000 (OK), no reason
ERROR 2019-07-16 10:16:36,351 - Function: screen, args: (<adb.device.Device object at 0x000001ABC6560668>, 'smurfscreen.png'), kwargs {}, Result: ERROR: 'FAIL' 0022device '127.0.0.1:62025' not found
ERROR 2019-07-16 16:39:09,341 - Function: screen, args: (<adb.device.Device object at 0x000001ABC65606D8>, 'mainscreen.png'), kwargs {}, Result: bytearray index out of range
ERROR 2019-07-16 16:39:09,894 - Attempting a reconnect in 0.62s
Traceback (most recent call last):
  File "C:\Program Files\Python36\lib\site-packages\discord\gateway.py", line 464, in poll_event
    msg = await self.recv()
  File "C:\Program Files\Python36\lib\site-packages\websockets\protocol.py", line 350, in recv
    yield from self.ensure_open()
  File "C:\Program Files\Python36\lib\site-packages\websockets\protocol.py", line 501, in ensure_open
    self.close_code, self.close_reason) from self.transfer_data_exc
websockets.exceptions.ConnectionClosed: WebSocket connection is closed: code = 1000 (OK), no reason

The above exception was the direct cause of the following exception:

Traceback (most recent call last):
  File "C:\Program Files\Python36\lib\site-packages\discord\client.py", line 393, in connect
    await self._connect()
  File "C:\Program Files\Python36\lib\site-packages\discord\client.py", line 358, in _connect
    await self.ws.poll_event()
  File "C:\Program Files\Python36\lib\site-packages\discord\gateway.py", line 472, in poll_event
    raise ConnectionClosed(exc, shard_id=self.shard_id) from exc
discord.errors.ConnectionClosed: WebSocket connection is closed: code = 1000 (OK), no reason
ERROR 2019-07-17 01:47:44,727 - Attempting a reconnect in 0.90s
Traceback (most recent call last):
  File "C:\Program Files\Python36\lib\site-packages\discord\gateway.py", line 464, in poll_event
    msg = await self.recv()
  File "C:\Program Files\Python36\lib\site-packages\websockets\protocol.py", line 350, in recv
    yield from self.ensure_open()
  File "C:\Program Files\Python36\lib\site-packages\websockets\protocol.py", line 501, in ensure_open
    self.close_code, self.close_reason) from self.transfer_data_exc
websockets.exceptions.ConnectionClosed: WebSocket connection is closed: code = 1000 (OK), no reason

The above exception was the direct cause of the following exception:

Traceback (most recent call last):
  File "C:\Program Files\Python36\lib\site-packages\discord\client.py", line 393, in connect
    await self._connect()
  File "C:\Program Files\Python36\lib\site-packages\discord\client.py", line 358, in _connect
    await self.ws.poll_event()
  File "C:\Program Files\Python36\lib\site-packages\discord\gateway.py", line 472, in poll_event
    raise ConnectionClosed(exc, shard_id=self.shard_id) from exc
discord.errors.ConnectionClosed: WebSocket connection is closed: code = 1000 (OK), no reason
ERROR 2019-07-17 01:49:30,661 - Attempting a reconnect in 0.10s
Traceback (most recent call last):
  File "C:\Program Files\Python36\lib\site-packages\aiohttp\connector.py", line 924, in _wrap_create_connection
    await self._loop.create_connection(*args, **kwargs))
  File "C:\Program Files\Python36\lib\asyncio\base_events.py", line 783, in create_connection
    raise exceptions[0]
  File "C:\Program Files\Python36\lib\asyncio\base_events.py", line 770, in create_connection
    yield from self.sock_connect(sock, address)
  File "C:\Program Files\Python36\lib\asyncio\selector_events.py", line 450, in sock_connect
    return (yield from fut)
  File "C:\Program Files\Python36\lib\asyncio\selector_events.py", line 480, in _sock_connect_cb
    raise OSError(err, 'Connect call failed %s' % (address,))
TimeoutError: [Errno 10060] Connect call failed ('162.159.135.233', 443)

The above exception was the direct cause of the following exception:

Traceback (most recent call last):
  File "C:\Program Files\Python36\lib\site-packages\discord\client.py", line 393, in connect
    await self._connect()
  File "C:\Program Files\Python36\lib\site-packages\discord\client.py", line 355, in _connect
    self.ws = await asyncio.wait_for(coro, timeout=180.0, loop=self.loop)
  File "C:\Program Files\Python36\lib\asyncio\tasks.py", line 358, in wait_for
    return fut.result()
  File "C:\Program Files\Python36\lib\site-packages\discord\gateway.py", line 219, in from_client
    gateway = await client.http.get_gateway()
  File "C:\Program Files\Python36\lib\site-packages\discord\http.py", line 780, in get_gateway
    data = await self.request(Route('GET', '/gateway'))
  File "C:\Program Files\Python36\lib\site-packages\discord\http.py", line 158, in request
    async with self.__session.request(method, url, **kwargs) as r:
  File "C:\Program Files\Python36\lib\site-packages\aiohttp\client.py", line 1005, in __aenter__
    self._resp = await self._coro
  File "C:\Program Files\Python36\lib\site-packages\aiohttp\client.py", line 476, in _request
    timeout=real_timeout
  File "C:\Program Files\Python36\lib\site-packages\aiohttp\connector.py", line 522, in connect
    proto = await self._create_connection(req, traces, timeout)
  File "C:\Program Files\Python36\lib\site-packages\aiohttp\connector.py", line 854, in _create_connection
    req, traces, timeout)
  File "C:\Program Files\Python36\lib\site-packages\aiohttp\connector.py", line 992, in _create_direct_connection
    raise last_exc
  File "C:\Program Files\Python36\lib\site-packages\aiohttp\connector.py", line 974, in _create_direct_connection
    req=req, client_error=client_error)
  File "C:\Program Files\Python36\lib\site-packages\aiohttp\connector.py", line 931, in _wrap_create_connection
    raise client_error(req.connection_key, exc) from exc
aiohttp.client_exceptions.ClientConnectorError: Cannot connect to host discordapp.com:443 ssl:None [Connect call failed ('162.159.135.233', 443)]
ERROR 2019-07-17 01:51:15,847 - Attempting a reconnect in 0.05s
Traceback (most recent call last):
  File "C:\Program Files\Python36\lib\site-packages\aiohttp\connector.py", line 924, in _wrap_create_connection
    await self._loop.create_connection(*args, **kwargs))
  File "C:\Program Files\Python36\lib\asyncio\base_events.py", line 783, in create_connection
    raise exceptions[0]
  File "C:\Program Files\Python36\lib\asyncio\base_events.py", line 770, in create_connection
    yield from self.sock_connect(sock, address)
  File "C:\Program Files\Python36\lib\asyncio\selector_events.py", line 450, in sock_connect
    return (yield from fut)
  File "C:\Program Files\Python36\lib\asyncio\selector_events.py", line 480, in _sock_connect_cb
    raise OSError(err, 'Connect call failed %s' % (address,))
TimeoutError: [Errno 10060] Connect call failed ('162.159.135.233', 443)

The above exception was the direct cause of the following exception:

Traceback (most recent call last):
  File "C:\Program Files\Python36\lib\site-packages\discord\client.py", line 393, in connect
    await self._connect()
  File "C:\Program Files\Python36\lib\site-packages\discord\client.py", line 355, in _connect
    self.ws = await asyncio.wait_for(coro, timeout=180.0, loop=self.loop)
  File "C:\Program Files\Python36\lib\asyncio\tasks.py", line 358, in wait_for
    return fut.result()
  File "C:\Program Files\Python36\lib\site-packages\discord\gateway.py", line 219, in from_client
    gateway = await client.http.get_gateway()
  File "C:\Program Files\Python36\lib\site-packages\discord\http.py", line 780, in get_gateway
    data = await self.request(Route('GET', '/gateway'))
  File "C:\Program Files\Python36\lib\site-packages\discord\http.py", line 158, in request
    async with self.__session.request(method, url, **kwargs) as r:
  File "C:\Program Files\Python36\lib\site-packages\aiohttp\client.py", line 1005, in __aenter__
    self._resp = await self._coro
  File "C:\Program Files\Python36\lib\site-packages\aiohttp\client.py", line 476, in _request
    timeout=real_timeout
  File "C:\Program Files\Python36\lib\site-packages\aiohttp\connector.py", line 522, in connect
    proto = await self._create_connection(req, traces, timeout)
  File "C:\Program Files\Python36\lib\site-packages\aiohttp\connector.py", line 854, in _create_connection
    req, traces, timeout)
  File "C:\Program Files\Python36\lib\site-packages\aiohttp\connector.py", line 992, in _create_direct_connection
    raise last_exc
  File "C:\Program Files\Python36\lib\site-packages\aiohttp\connector.py", line 974, in _create_direct_connection
    req=req, client_error=client_error)
  File "C:\Program Files\Python36\lib\site-packages\aiohttp\connector.py", line 931, in _wrap_create_connection
    raise client_error(req.connection_key, exc) from exc
aiohttp.client_exceptions.ClientConnectorError: Cannot connect to host discordapp.com:443 ssl:None [Connect call failed ('162.159.135.233', 443)]
ERROR 2019-07-17 11:13:48,664 - Attempting a reconnect in 0.78s
Traceback (most recent call last):
  File "C:\Program Files\Python36\lib\site-packages\discord\gateway.py", line 464, in poll_event
    msg = await self.recv()
  File "C:\Program Files\Python36\lib\site-packages\websockets\protocol.py", line 350, in recv
    yield from self.ensure_open()
  File "C:\Program Files\Python36\lib\site-packages\websockets\protocol.py", line 501, in ensure_open
    self.close_code, self.close_reason) from self.transfer_data_exc
websockets.exceptions.ConnectionClosed: WebSocket connection is closed: code = 1000 (OK), no reason

The above exception was the direct cause of the following exception:

Traceback (most recent call last):
  File "C:\Program Files\Python36\lib\site-packages\discord\client.py", line 393, in connect
    await self._connect()
  File "C:\Program Files\Python36\lib\site-packages\discord\client.py", line 358, in _connect
    await self.ws.poll_event()
  File "C:\Program Files\Python36\lib\site-packages\discord\gateway.py", line 472, in poll_event
    raise ConnectionClosed(exc, shard_id=self.shard_id) from exc
discord.errors.ConnectionClosed: WebSocket connection is closed: code = 1000 (OK), no reason
ERROR 2019-07-17 11:13:58,634 - Function: screen, args: (<adb.device.Device object at 0x000001ABC6560668>, 'smurfscreen.png'), kwargs {}, Result: ERROR: 'FAIL' 0022device '127.0.0.1:62025' not found
ERROR 2019-07-18 15:13:46,293 - Function: screen, args: (<adb.device.Device object at 0x000001ABC6560668>, 'smurfscreen.png'), kwargs {}, Result: bytearray index out of range
ERROR 2019-07-18 15:13:46,382 - Attempting a reconnect in 1.59s
Traceback (most recent call last):
  File "C:\Program Files\Python36\lib\site-packages\discord\gateway.py", line 464, in poll_event
    msg = await self.recv()
  File "C:\Program Files\Python36\lib\site-packages\websockets\protocol.py", line 350, in recv
    yield from self.ensure_open()
  File "C:\Program Files\Python36\lib\site-packages\websockets\protocol.py", line 501, in ensure_open
    self.close_code, self.close_reason) from self.transfer_data_exc
websockets.exceptions.ConnectionClosed: WebSocket connection is closed: code = 1000 (OK), no reason

The above exception was the direct cause of the following exception:

Traceback (most recent call last):
  File "C:\Program Files\Python36\lib\site-packages\discord\client.py", line 393, in connect
    await self._connect()
  File "C:\Program Files\Python36\lib\site-packages\discord\client.py", line 358, in _connect
    await self.ws.poll_event()
  File "C:\Program Files\Python36\lib\site-packages\discord\gateway.py", line 472, in poll_event
    raise ConnectionClosed(exc, shard_id=self.shard_id) from exc
discord.errors.ConnectionClosed: WebSocket connection is closed: code = 1000 (OK), no reason
ERROR 2019-07-18 15:13:56,355 - Function: screen, args: (<adb.device.Device object at 0x000001ABC6560668>, 'smurfscreen.png'), kwargs {}, Result: ERROR: 'FAIL' 0022device '127.0.0.1:62025' not found
ERROR 2019-07-18 15:14:06,414 - Function: screen, args: (<adb.device.Device object at 0x000001ABC6560668>, 'smurfscreen.png'), kwargs {}, Result: ERROR: 'FAIL' 0022device '127.0.0.1:62025' not found
ERROR 2019-07-19 15:57:41,998 - Function: compare_image, args: ('temp.png', 'play.png'), kwargs {}, Result: OpenCV(4.0.1) C:\projects\opencv-python\opencv\modules\imgproc\src\color.cpp:181: error: (-215:Assertion failed) !_src.empty() in function 'cv::cvtColor'

ERROR 2019-07-19 23:15:18,202 - Function: screen, args: (<adb.device.Device object at 0x000001D884C31710>, 'smurfscreen.png'), kwargs {}, Result: ERROR: 'FAIL' 0022device '127.0.0.1:62025' not found
ERROR 2019-07-19 23:15:28,259 - Function: screen, args: (<adb.device.Device object at 0x000001D884C31710>, 'smurfscreen.png'), kwargs {}, Result: ERROR: 'FAIL' 0022device '127.0.0.1:62025' not found
ERROR 2019-07-19 23:25:49,646 - Function: screen, args: (<adb.device.Device object at 0x000001D884C31710>, 'smurfscreen.png'), kwargs {}, Result: ERROR: 'FAIL' 0022device '127.0.0.1:62025' not found
ERROR 2019-07-21 18:08:37,903 - Function: compare_image, args: ('smurfscreen.png', 'buff.png'), kwargs {}, Result: OpenCV(4.0.1) C:\projects\opencv-python\opencv\modules\imgproc\src\color.cpp:181: error: (-215:Assertion failed) !_src.empty() in function 'cv::cvtColor'

ERROR 2019-07-22 17:20:09,068 - Function: screen, args: (<adb.device.Device object at 0x000001D884C31710>, 'smurfscreen.png'), kwargs {}, Result: bytearray index out of range
ERROR 2019-07-22 17:20:09,154 - Attempting a reconnect in 0.79s
Traceback (most recent call last):
  File "C:\Program Files\Python36\lib\site-packages\discord\gateway.py", line 464, in poll_event
    msg = await self.recv()
  File "C:\Program Files\Python36\lib\site-packages\websockets\protocol.py", line 350, in recv
    yield from self.ensure_open()
  File "C:\Program Files\Python36\lib\site-packages\websockets\protocol.py", line 501, in ensure_open
    self.close_code, self.close_reason) from self.transfer_data_exc
websockets.exceptions.ConnectionClosed: WebSocket connection is closed: code = 1000 (OK), no reason

The above exception was the direct cause of the following exception:

Traceback (most recent call last):
  File "C:\Program Files\Python36\lib\site-packages\discord\client.py", line 393, in connect
    await self._connect()
  File "C:\Program Files\Python36\lib\site-packages\discord\client.py", line 358, in _connect
    await self.ws.poll_event()
  File "C:\Program Files\Python36\lib\site-packages\discord\gateway.py", line 472, in poll_event
    raise ConnectionClosed(exc, shard_id=self.shard_id) from exc
discord.errors.ConnectionClosed: WebSocket connection is closed: code = 1000 (OK), no reason
ERROR 2019-07-22 17:20:19,121 - Function: screen, args: (<adb.device.Device object at 0x000001D884C31710>, 'smurfscreen.png'), kwargs {}, Result: ERROR: 'FAIL' 0022device '127.0.0.1:62025' not found
ERROR 2019-07-22 23:15:21,744 - Function: screen, args: (<adb.device.Device object at 0x000001D884C31710>, 'smurfscreen.png'), kwargs {}, Result: bytearray index out of range
ERROR 2019-07-22 23:15:31,784 - Function: screen, args: (<adb.device.Device object at 0x000001D884C31710>, 'smurfscreen.png'), kwargs {}, Result: ERROR: 'FAIL' 0022device '127.0.0.1:62025' not found
ERROR 2019-07-22 23:25:49,390 - Function: screen, args: (<adb.device.Device object at 0x000001D884C31710>, 'smurfscreen.png'), kwargs {}, Result: ERROR: 'FAIL' 0022device '127.0.0.1:62025' not found
ERROR 2019-07-22 23:25:59,410 - Function: screen, args: (<adb.device.Device object at 0x000001D884C31710>, 'smurfscreen.png'), kwargs {}, Result: ERROR: 'FAIL' 0022device '127.0.0.1:62025' not found
ERROR 2019-07-23 23:30:14,959 - Function: screen, args: (<adb.device.Device object at 0x000001D884C31710>, 'smurfscreen.png'), kwargs {}, Result: ERROR: connecting to 127.0.0.1:5037 [WinError 10061] Es konnte keine Verbindung hergestellt werden, da der Zielcomputer die Verbindung verweigerte.
Is adb running on your computer?
ERROR 2019-07-26 07:01:58,058 - Function: screen, args: (<adb.device.Device object at 0x000001C3317715F8>, 'smurfscreen.png'), kwargs {}, Result: ERROR: 'FAIL' 0022device '127.0.0.1:62025' not found
ERROR 2019-07-26 09:22:22,475 - Function: compare_image, args: ('smurfscreen.png', 'buff.png'), kwargs {}, Result: OpenCV(4.0.1) C:\projects\opencv-python\opencv\modules\imgproc\src\color.cpp:181: error: (-215:Assertion failed) !_src.empty() in function 'cv::cvtColor'

ERROR 2019-07-26 09:28:49,022 - Function: screen, args: (<adb.device.Device object at 0x000001C3317715F8>, 'smurfscreen.png'), kwargs {}, Result: bytearray index out of range
ERROR 2019-07-26 09:28:59,059 - Function: screen, args: (<adb.device.Device object at 0x000001C3317715F8>, 'smurfscreen.png'), kwargs {}, Result: ERROR: 'FAIL' 0022device '127.0.0.1:62025' not found
ERROR 2019-07-26 10:05:48,497 - Function: screen, args: (<adb.device.Device object at 0x000001C3317715F8>, 'smurfscreen.png'), kwargs {}, Result: bytearray index out of range
ERROR 2019-07-26 10:05:58,554 - Function: screen, args: (<adb.device.Device object at 0x000001C3317715F8>, 'smurfscreen.png'), kwargs {}, Result: ERROR: 'FAIL' 0022device '127.0.0.1:62025' not found
ERROR 2019-07-26 14:51:57,641 - Function: screen, args: (<adb.device.Device object at 0x000001C3317715F8>, 'smurfscreen.png'), kwargs {}, Result: ERROR: 'FAIL' 0022device '127.0.0.1:62025' not found
ERROR 2019-07-26 23:53:58,994 - Task exception was never retrieved
future: <Task finished coro=<check_nox() done, defined at D:/MSL_Python/main.py:713> exception=OSError(22, 'Nur ein Teil der ReadProcessMemory- oder WriteProcessMemory-Anforderung wurde abgeschlossen')>
Traceback (most recent call last):
  File "D:/MSL_Python/main.py", line 732, in check_nox
    pid[emu] = get_pid_by_cmd(msl_find_str)
  File "D:/MSL_Python/main.py", line 87, in call
    result = func(*args, **kwargs)
  File "D:/MSL_Python/main.py", line 642, in get_pid_by_cmd
    for pid, cmdline in process_cmd_lines().items():
  File "D:/MSL_Python/main.py", line 631, in process_cmd_lines
    cmd_lines[process.pid] = process.cmdline()
  File "C:\Program Files\Python36\lib\site-packages\psutil\__init__.py", line 786, in cmdline
    return self._proc.cmdline()
  File "C:\Program Files\Python36\lib\site-packages\psutil\_pswindows.py", line 667, in wrapper
    return fun(self, *args, **kwargs)
  File "C:\Program Files\Python36\lib\site-packages\psutil\_pswindows.py", line 745, in cmdline
    ret = cext.proc_cmdline(self.pid, use_peb=True)
OSError: [WinError 299] Nur ein Teil der ReadProcessMemory- oder WriteProcessMemory-Anforderung wurde abgeschlossen: 'originated from ReadProcessMemory'
ERROR 2019-07-27 09:40:15,199 - Function: screen, args: (<adb.device.Device object at 0x000001C3317715F8>, 'smurfscreen.png'), kwargs {}, Result: ERROR: 'FAIL' 0022device '127.0.0.1:62025' not found
ERROR 2019-07-27 12:53:43,229 - Function: screen, args: (<adb.device.Device object at 0x000001C3317715F8>, 'smurfscreen.png'), kwargs {}, Result: ERROR: 'FAIL' 0022device '127.0.0.1:62025' not found
ERROR 2019-07-28 20:25:05,313 - Function: compare_image, args: ('smurfscreen.png', 'buff.png'), kwargs {}, Result: OpenCV(4.0.1) C:\projects\opencv-python\opencv\modules\imgproc\src\color.cpp:181: error: (-215:Assertion failed) !_src.empty() in function 'cv::cvtColor'

ERROR 2019-07-28 23:20:39,101 - Function: screen, args: (<adb.device.Device object at 0x000001C3317715F8>, 'smurfscreen.png'), kwargs {}, Result: ERROR: 'FAIL' 0022device '127.0.0.1:62025' not found
ERROR 2019-07-28 23:20:49,151 - Function: screen, args: (<adb.device.Device object at 0x000001C3317715F8>, 'smurfscreen.png'), kwargs {}, Result: ERROR: 'FAIL' 0022device '127.0.0.1:62025' not found
ERROR 2019-07-29 02:51:06,537 - Function: screen, args: (<adb.device.Device object at 0x000001C3317715F8>, 'smurfscreen.png'), kwargs {}, Result: bytearray index out of range
ERROR 2019-07-29 02:51:16,564 - Function: screen, args: (<adb.device.Device object at 0x000001C3317715F8>, 'smurfscreen.png'), kwargs {}, Result: ERROR: 'FAIL' 0022device '127.0.0.1:62025' not found
ERROR 2019-07-29 06:09:37,408 - Function: screen, args: (<adb.device.Device object at 0x000001C3317715F8>, 'smurfscreen.png'), kwargs {}, Result: bytearray index out of range
ERROR 2019-07-29 06:09:47,428 - Function: screen, args: (<adb.device.Device object at 0x000001C3317715F8>, 'smurfscreen.png'), kwargs {}, Result: ERROR: 'FAIL' 0022device '127.0.0.1:62025' not found
ERROR 2019-07-29 07:38:07,399 - Function: screen, args: (<adb.device.Device object at 0x000001C3317715F8>, 'smurfscreen.png'), kwargs {}, Result: bytearray index out of range
ERROR 2019-07-29 07:38:17,446 - Function: screen, args: (<adb.device.Device object at 0x000001C3317715F8>, 'smurfscreen.png'), kwargs {}, Result: ERROR: 'FAIL' 0022device '127.0.0.1:62025' not found
ERROR 2019-07-29 08:04:12,437 - Function: screen, args: (<adb.device.Device object at 0x000001C3317715F8>, 'smurfscreen.png'), kwargs {}, Result: ERROR: 'FAIL' 0022device '127.0.0.1:62025' not found
ERROR 2019-07-29 09:09:07,227 - Function: screen, args: (<adb.device.Device object at 0x000001C3317715F8>, 'smurfscreen.png'), kwargs {}, Result: bytearray index out of range
ERROR 2019-07-29 09:09:17,266 - Function: screen, args: (<adb.device.Device object at 0x000001C3317715F8>, 'smurfscreen.png'), kwargs {}, Result: ERROR: 'FAIL' 0022device '127.0.0.1:62025' not found
ERROR 2019-07-29 12:46:43,122 - Function: screen, args: (<adb.device.Device object at 0x000001C3317715F8>, 'smurfscreen.png'), kwargs {}, Result: ERROR: 'FAIL' 0022device '127.0.0.1:62025' not found
ERROR 2019-07-29 15:29:41,856 - Function: screen, args: (<adb.device.Device object at 0x000001C3317715F8>, 'smurfscreen.png'), kwargs {}, Result: ERROR: 'FAIL' 0022device '127.0.0.1:62025' not found
ERROR 2019-07-29 15:40:05,267 - Function: screen, args: (<adb.device.Device object at 0x000001C3317715F8>, 'smurfscreen.png'), kwargs {}, Result: ERROR: 'FAIL' 0022device '127.0.0.1:62025' not found
ERROR 2019-07-30 00:48:14,334 - Function: screen, args: (<adb.device.Device object at 0x000001C3317715F8>, 'smurfscreen.png'), kwargs {}, Result: bytearray index out of range
ERROR 2019-07-30 00:48:24,393 - Function: screen, args: (<adb.device.Device object at 0x000001C3317715F8>, 'smurfscreen.png'), kwargs {}, Result: ERROR: 'FAIL' 0022device '127.0.0.1:62025' not found
ERROR 2019-07-30 12:10:42,507 - Function: screen, args: (<adb.device.Device object at 0x000001C3317715F8>, 'smurfscreen.png'), kwargs {}, Result: ERROR: 'FAIL' 0022device '127.0.0.1:62025' not found
ERROR 2019-07-30 14:16:13,369 - Function: screen, args: (<adb.device.Device object at 0x000001C3317715F8>, 'smurfscreen.png'), kwargs {}, Result: ERROR: 'FAIL' 0022device '127.0.0.1:62025' not found
ERROR 2019-07-31 07:45:50,936 - Function: screen, args: (<adb.device.Device object at 0x000001C3317715F8>, 'smurfscreen.png'), kwargs {}, Result: ERROR: 'FAIL' 0022device '127.0.0.1:62025' not found
ERROR 2019-07-31 11:30:51,143 - Function: screen, args: (<adb.device.Device object at 0x000001C3317715F8>, 'smurfscreen.png'), kwargs {}, Result: ERROR: 'FAIL' 0022device '127.0.0.1:62025' not found
ERROR 2019-07-31 15:10:45,685 - Function: screen, args: (<adb.device.Device object at 0x000001C3317715F8>, 'smurfscreen.png'), kwargs {}, Result: ERROR: 'FAIL' 0022device '127.0.0.1:62025' not found
ERROR 2019-07-31 15:10:55,758 - Function: screen, args: (<adb.device.Device object at 0x000001C3317715F8>, 'smurfscreen.png'), kwargs {}, Result: ERROR: 'FAIL' 0022device '127.0.0.1:62025' not found
ERROR 2019-07-31 15:11:05,823 - Function: screen, args: (<adb.device.Device object at 0x000001C3317715F8>, 'smurfscreen.png'), kwargs {}, Result: ERROR: 'FAIL' 0022device '127.0.0.1:62025' not found
ERROR 2019-07-31 15:11:15,878 - Function: screen, args: (<adb.device.Device object at 0x000001C3317715F8>, 'smurfscreen.png'), kwargs {}, Result: ERROR: 'FAIL' 0022device '127.0.0.1:62025' not found
ERROR 2019-07-31 15:11:25,922 - Function: screen, args: (<adb.device.Device object at 0x000001C3317715F8>, 'smurfscreen.png'), kwargs {}, Result: ERROR: 'FAIL' 0022device '127.0.0.1:62025' not found
ERROR 2019-07-31 15:11:35,959 - Function: screen, args: (<adb.device.Device object at 0x000001C3317715F8>, 'smurfscreen.png'), kwargs {}, Result: ERROR: 'FAIL' 0022device '127.0.0.1:62025' not found
ERROR 2019-07-31 15:12:27,904 - Function: screen, args: (<adb.device.Device object at 0x000001C3317715F8>, 'smurfscreen.png'), kwargs {}, Result: ERROR: 'FAIL' 0022device '127.0.0.1:62025' not found
ERROR 2019-07-31 15:12:37,947 - Function: screen, args: (<adb.device.Device object at 0x000001C3317715F8>, 'smurfscreen.png'), kwargs {}, Result: ERROR: 'FAIL' 0022device '127.0.0.1:62025' not found
ERROR 2019-07-31 15:12:47,998 - Function: screen, args: (<adb.device.Device object at 0x000001C3317715F8>, 'smurfscreen.png'), kwargs {}, Result: ERROR: 'FAIL' 0022device '127.0.0.1:62025' not found
ERROR 2019-07-31 15:53:51,127 - Function: screen, args: (<adb.device.Device object at 0x000001C3317715F8>, 'smurfscreen.png'), kwargs {}, Result: ERROR: connecting to 127.0.0.1:5037 [WinError 10061] Es konnte keine Verbindung hergestellt werden, da der Zielcomputer die Verbindung verweigerte.
Is adb running on your computer?
ERROR 2021-01-12 20:27:54,165 - Function: connect_adb, args: (), kwargs {}, Result: ERROR: connecting to 127.0.0.1:5037 [WinError 10061] Es konnte keine Verbindung hergestellt werden, da der Zielcomputer die Verbindung verweigerte.
Is adb running on your computer?
ERROR 2021-01-16 00:43:58,530 - Task exception was never retrieved
future: <Task finished coro=<check_titan() done, defined at D:/MSL_Python/main.py:656> exception=KeyError('BASE_BATTLE_TIME',)>
Traceback (most recent call last):
  File "D:/MSL_Python/main.py", line 672, in check_titan
    time = await titan_time()
  File "D:/MSL_Python/main.py", line 1082, in titan_time
    base_battle_time = TITAN_CFG['BASE_BATTLE_TIME']
  File "C:\Program Files\Python36\lib\site-packages\configobj.py", line 554, in __getitem__
    val = dict.__getitem__(self, key)
KeyError: 'BASE_BATTLE_TIME'
ERROR 2021-01-16 00:45:01,735 - Task exception was never retrieved
future: <Task finished coro=<check_titan() done, defined at D:/MSL_Python/main.py:656> exception=KeyError('BASE_BATTLE_TIME',)>
Traceback (most recent call last):
  File "D:/MSL_Python/main.py", line 672, in check_titan
    time = await titan_time()
  File "D:/MSL_Python/main.py", line 1082, in titan_time
    base_battle_time = TITAN_CFG['BASE_BATTLE_TIME']
  File "C:\Program Files\Python36\lib\site-packages\configobj.py", line 554, in __getitem__
    val = dict.__getitem__(self, key)
KeyError: 'BASE_BATTLE_TIME'
CRITICAL 2021-01-16 00:45:51,797 - Restarting Nox - Nox_1
ERROR 2021-01-16 00:45:51,798 - Task exception was never retrieved
future: <Task finished coro=<check_nox() done, defined at D:/MSL_Python/main.py:719> exception=AttributeError("'NoneType' object has no attribute 'send'",)>
Traceback (most recent call last):
  File "D:/MSL_Python/main.py", line 751, in check_nox
    await user.send(f'No PID found for {emu}, restarting Emulator')
AttributeError: 'NoneType' object has no attribute 'send'
ERROR 2021-01-19 15:07:27,641 - Exception in default exception handler
Traceback (most recent call last):
  File "C:\Program Files\Python36\lib\asyncio\base_events.py", line 1299, in call_exception_handler
    self.default_exception_handler(context)
  File "C:\Program Files\Python36\lib\asyncio\base_events.py", line 1271, in default_exception_handler
    value = repr(value)
  File "C:\Program Files\Python36\lib\asyncio\base_tasks.py", line 15, in _task_repr_info
    coro = coroutines._format_coroutine(task._coro)
  File "C:\Program Files\Python36\lib\asyncio\coroutines.py", line 276, in _format_coroutine
    assert iscoroutine(coro)
AssertionError
ERROR 2021-01-19 15:10:08,480 - Exception in default exception handler
Traceback (most recent call last):
  File "C:\Program Files\Python36\lib\asyncio\base_events.py", line 1299, in call_exception_handler
    self.default_exception_handler(context)
  File "C:\Program Files\Python36\lib\asyncio\base_events.py", line 1271, in default_exception_handler
    value = repr(value)
  File "C:\Program Files\Python36\lib\asyncio\base_tasks.py", line 15, in _task_repr_info
    coro = coroutines._format_coroutine(task._coro)
  File "C:\Program Files\Python36\lib\asyncio\coroutines.py", line 276, in _format_coroutine
    assert iscoroutine(coro)
AssertionError
ERROR 2021-01-19 17:15:08,947 - Task exception was never retrieved
future: <Task finished coro=<check_titan() done, defined at D:/MSL_Python/main.py:733> exception=KeyError('BASE_BATTLE_TIME',)>
Traceback (most recent call last):
  File "D:/MSL_Python/main.py", line 749, in check_titan
    time = await titan_time()
  File "D:/MSL_Python/main.py", line 1071, in titan_time
    base_battle_time = TITAN_CFG['BASE_BATTLE_TIME']
  File "C:\Program Files\Python36\lib\site-packages\configobj.py", line 554, in __getitem__
    val = dict.__getitem__(self, key)
KeyError: 'BASE_BATTLE_TIME'
ERROR 2021-01-19 17:17:47,282 - Task exception was never retrieved
future: <Task finished coro=<check_titan() done, defined at D:/MSL_Python/main.py:733> exception=KeyError('BASE_BATTLE_TIME',)>
Traceback (most recent call last):
  File "D:/MSL_Python/main.py", line 749, in check_titan
    time = titan_time()
  File "D:/MSL_Python/main.py", line 192, in call
    result = func(*args, **kwargs)
  File "D:/MSL_Python/main.py", line 1071, in titan_time
    base_battle_time = TITAN_CFG['BASE_BATTLE_TIME']
  File "C:\Program Files\Python36\lib\site-packages\configobj.py", line 554, in __getitem__
    val = dict.__getitem__(self, key)
KeyError: 'BASE_BATTLE_TIME'
ERROR 2021-01-19 17:19:09,390 - Task exception was never retrieved
future: <Task finished coro=<check_titan() done, defined at D:/MSL_Python/main.py:733> exception=KeyError('BASE_BATTLE_TIME',)>
Traceback (most recent call last):
  File "D:/MSL_Python/main.py", line 749, in check_titan
    time = titan_time()
  File "D:/MSL_Python/main.py", line 192, in call
    result = func(*args, **kwargs)
  File "D:/MSL_Python/main.py", line 1071, in titan_time
    base_battle_time = TITAN_CFG['BASE_BATTLE_TIME']
  File "C:\Program Files\Python36\lib\site-packages\configobj.py", line 554, in __getitem__
    val = dict.__getitem__(self, key)
KeyError: 'BASE_BATTLE_TIME'
ERROR 2021-01-19 17:19:38,580 - Task exception was never retrieved
future: <Task finished coro=<check_titan() done, defined at D:/MSL_Python/main.py:733> exception=KeyError('BASE_BATTLE_TIME',)>
Traceback (most recent call last):
  File "D:/MSL_Python/main.py", line 749, in check_titan
    time = titan_time()
  File "D:/MSL_Python/main.py", line 192, in call
    result = func(*args, **kwargs)
  File "D:/MSL_Python/main.py", line 1071, in titan_time
    base_battle_time = TITAN_CFG['BASE_BATTLE_TIME']
  File "C:\Program Files\Python36\lib\site-packages\configobj.py", line 554, in __getitem__
    val = dict.__getitem__(self, key)
KeyError: 'BASE_BATTLE_TIME'
ERROR 2021-02-27 18:01:37,316 - Task exception was never retrieved
future: <Task finished coro=<check_titan() done, defined at D:/MSL_Python/main.py:733> exception=KeyError('BASE_BATTLE_TIME',)>
Traceback (most recent call last):
  File "D:/MSL_Python/main.py", line 742, in check_titan
    time = titan_time()
  File "D:/MSL_Python/main.py", line 194, in call
    result = func(*args, **kwargs)
  File "D:/MSL_Python/main.py", line 1065, in titan_time
    base_battle_time = TITAN_CFG['BASE_BATTLE_TIME']
  File "C:\Program Files\Python36\lib\site-packages\configobj.py", line 554, in __getitem__
    val = dict.__getitem__(self, key)
KeyError: 'BASE_BATTLE_TIME'
CRITICAL 2021-02-27 18:02:27,406 - Restarting Nox - Nox_1
ERROR 2021-02-27 18:02:27,406 - Task exception was never retrieved
future: <Task finished coro=<check_nox() done, defined at D:/MSL_Python/main.py:795> exception=AttributeError("'NoneType' object has no attribute 'send'",)>
Traceback (most recent call last):
  File "D:/MSL_Python/main.py", line 827, in check_nox
    await user.send(f'No PID found for {emu}, restarting Emulator')
AttributeError: 'NoneType' object has no attribute 'send'
ERROR 2021-02-27 18:03:57,691 - Task exception was never retrieved
future: <Task finished coro=<check_titan() done, defined at D:/MSL_Python/main.py:733> exception=KeyError('BASE_BATTLE_TIME',)>
Traceback (most recent call last):
  File "D:/MSL_Python/main.py", line 742, in check_titan
    time = titan_time()
  File "D:/MSL_Python/main.py", line 194, in call
    result = func(*args, **kwargs)
  File "D:/MSL_Python/main.py", line 1065, in titan_time
    base_battle_time = TITAN_CFG['BASE_BATTLE_TIME']
  File "C:\Program Files\Python36\lib\site-packages\configobj.py", line 554, in __getitem__
    val = dict.__getitem__(self, key)
KeyError: 'BASE_BATTLE_TIME'
CRITICAL 2021-02-27 18:04:47,767 - Restarting Nox - Nox_1
ERROR 2021-02-27 18:04:47,768 - Task exception was never retrieved
future: <Task finished coro=<check_nox() done, defined at D:/MSL_Python/main.py:795> exception=AttributeError("'NoneType' object has no attribute 'send'",)>
Traceback (most recent call last):
  File "D:/MSL_Python/main.py", line 827, in check_nox
    await user.send(f'No PID found for {emu}, restarting Emulator')
AttributeError: 'NoneType' object has no attribute 'send'
ERROR 2021-02-27 18:05:14,210 - Task exception was never retrieved
future: <Task finished coro=<check_titan() done, defined at D:/MSL_Python/main.py:733> exception=KeyError('BASE_BATTLE_TIME',)>
Traceback (most recent call last):
  File "D:/MSL_Python/main.py", line 743, in check_titan
    time = titan_time()
  File "D:/MSL_Python/main.py", line 194, in call
    result = func(*args, **kwargs)
  File "D:/MSL_Python/main.py", line 1067, in titan_time
    base_battle_time = TITAN_CFG['BASE_BATTLE_TIME']
  File "C:\Program Files\Python36\lib\site-packages\configobj.py", line 554, in __getitem__
    val = dict.__getitem__(self, key)
KeyError: 'BASE_BATTLE_TIME'
ERROR 2021-02-27 18:05:44,656 - Task exception was never retrieved
future: <Task finished coro=<check_titan() done, defined at D:/MSL_Python/main.py:733> exception=KeyError('BASE_BATTLE_TIME',)>
Traceback (most recent call last):
  File "D:/MSL_Python/main.py", line 743, in check_titan
    time = titan_time()
  File "D:/MSL_Python/main.py", line 194, in call
    result = func(*args, **kwargs)
  File "D:/MSL_Python/main.py", line 1067, in titan_time
    base_battle_time = TITAN_CFG['BASE_BATTLE_TIME']
  File "C:\Program Files\Python36\lib\site-packages\configobj.py", line 554, in __getitem__
    val = dict.__getitem__(self, key)
KeyError: 'BASE_BATTLE_TIME'
CRITICAL 2021-02-27 18:06:34,721 - Restarting Nox - Nox_1
ERROR 2021-02-27 18:06:34,722 - Task exception was never retrieved
future: <Task finished coro=<check_nox() done, defined at D:/MSL_Python/main.py:797> exception=AttributeError("'NoneType' object has no attribute 'send'",)>
Traceback (most recent call last):
  File "D:/MSL_Python/main.py", line 829, in check_nox
    await user.send(f'No PID found for {emu}, restarting Emulator')
AttributeError: 'NoneType' object has no attribute 'send'
ERROR 2021-02-28 14:12:54,701 - Task exception was never retrieved
future: <Task finished coro=<check_titan() done, defined at D:/MSL_Python/main.py:733> exception=KeyError('BASE_BATTLE_TIME',)>
Traceback (most recent call last):
  File "D:/MSL_Python/main.py", line 743, in check_titan
    time = titan_time()
  File "D:/MSL_Python/main.py", line 194, in call
    result = func(*args, **kwargs)
  File "D:/MSL_Python/main.py", line 1067, in titan_time
    base_battle_time = TITAN_CFG['BASE_BATTLE_TIME']
  File "C:\Program Files\Python36\lib\site-packages\configobj.py", line 554, in __getitem__
    val = dict.__getitem__(self, key)
KeyError: 'BASE_BATTLE_TIME'
CRITICAL 2021-02-28 14:13:44,778 - Restarting Nox - Nox_1
ERROR 2021-02-28 14:13:44,778 - Task exception was never retrieved
future: <Task finished coro=<check_nox() done, defined at D:/MSL_Python/main.py:797> exception=AttributeError("'NoneType' object has no attribute 'send'",)>
Traceback (most recent call last):
  File "D:/MSL_Python/main.py", line 829, in check_nox
    await user.send(f'No PID found for {emu}, restarting Emulator')
AttributeError: 'NoneType' object has no attribute 'send'
ERROR 2021-02-28 14:13:49,814 - Task exception was never retrieved
future: <Task finished coro=<check_titan() done, defined at D:/MSL_Python/main.py:733> exception=KeyError('BASE_BATTLE_TIME',)>
Traceback (most recent call last):
  File "D:/MSL_Python/main.py", line 743, in check_titan
    time = titan_time()
  File "D:/MSL_Python/main.py", line 194, in call
    result = func(*args, **kwargs)
  File "D:/MSL_Python/main.py", line 1067, in titan_time
    base_battle_time = TITAN_CFG['BASE_BATTLE_TIME']
  File "C:\Program Files\Python36\lib\site-packages\configobj.py", line 554, in __getitem__
    val = dict.__getitem__(self, key)
KeyError: 'BASE_BATTLE_TIME'
CRITICAL 2021-02-28 14:14:39,896 - Restarting Nox - Nox_1
ERROR 2021-02-28 14:14:39,897 - Task exception was never retrieved
future: <Task finished coro=<check_nox() done, defined at D:/MSL_Python/main.py:797> exception=AttributeError("'NoneType' object has no attribute 'send'",)>
Traceback (most recent call last):
  File "D:/MSL_Python/main.py", line 829, in check_nox
    await user.send(f'No PID found for {emu}, restarting Emulator')
AttributeError: 'NoneType' object has no attribute 'send'
ERROR 2021-02-28 16:18:33,141 - Task exception was never retrieved
future: <Task finished coro=<check_titan() done, defined at D:/MSL_Python/main.py:733> exception=KeyError('BASE_BATTLE_TIME',)>
Traceback (most recent call last):
  File "D:/MSL_Python/main.py", line 743, in check_titan
    time = titan_time()
  File "D:/MSL_Python/main.py", line 194, in call
    result = func(*args, **kwargs)
  File "D:/MSL_Python/main.py", line 1067, in titan_time
    base_battle_time = TITAN_CFG['BASE_BATTLE_TIME']
  File "C:\Program Files\Python36\lib\site-packages\configobj.py", line 554, in __getitem__
    val = dict.__getitem__(self, key)
KeyError: 'BASE_BATTLE_TIME'
CRITICAL 2021-02-28 16:19:23,227 - Restarting Nox - Nox_1
ERROR 2021-02-28 16:19:23,227 - Task exception was never retrieved
future: <Task finished coro=<check_nox() done, defined at D:/MSL_Python/main.py:797> exception=AttributeError("'NoneType' object has no attribute 'send'",)>
Traceback (most recent call last):
  File "D:/MSL_Python/main.py", line 829, in check_nox
    await user.send(f'No PID found for {emu}, restarting Emulator')
AttributeError: 'NoneType' object has no attribute 'send'
CRITICAL 2021-02-28 16:42:52,475 - Restarting Nox - Nox_1
ERROR 2021-02-28 16:42:52,476 - Task exception was never retrieved
future: <Task finished coro=<check_nox() done, defined at D:/MSL_Python/main.py:794> exception=AttributeError("'NoneType' object has no attribute 'send'",)>
Traceback (most recent call last):
  File "D:/MSL_Python/main.py", line 826, in check_nox
    await user.send(f'No PID found for {emu}, restarting Emulator')
AttributeError: 'NoneType' object has no attribute 'send'
CRITICAL 2021-02-28 17:39:34,263 - Restarting Nox - Nox_1
ERROR 2021-02-28 17:39:34,263 - Task exception was never retrieved
future: <Task finished coro=<check_nox() done, defined at D:/MSL_Python/main.py:797> exception=AttributeError("'NoneType' object has no attribute 'send'",)>
Traceback (most recent call last):
  File "D:/MSL_Python/main.py", line 829, in check_nox
    await user.send(f'No PID found for {emu}, restarting Emulator')
AttributeError: 'NoneType' object has no attribute 'send'
CRITICAL 2021-02-28 17:41:16,103 - Restarting Nox - Nox_1
ERROR 2021-02-28 17:41:16,103 - Task exception was never retrieved
future: <Task finished coro=<check_nox() done, defined at D:/MSL_Python/main.py:797> exception=AttributeError("'NoneType' object has no attribute 'send'",)>
Traceback (most recent call last):
  File "D:/MSL_Python/main.py", line 830, in check_nox
    if type(user) != 'NoneType':
AttributeError: 'NoneType' object has no attribute 'send'
CRITICAL 2021-02-28 17:52:52,564 - Restarting Nox - Nox_1
ERROR 2021-02-28 17:52:52,564 - Task exception was never retrieved
future: <Task finished coro=<check_nox() done, defined at D:/MSL_Python/main.py:797> exception=AttributeError("'NoneType' object has no attribute 'send'",)>
Traceback (most recent call last):
  File "D:/MSL_Python/main.py", line 832, in check_nox
    await user.send(f'No PID found for {emu}, restarting Emulator')
AttributeError: 'NoneType' object has no attribute 'send'
CRITICAL 2021-02-28 17:55:00,325 - Restarting Nox - Nox_1
ERROR 2021-02-28 17:55:00,326 - Task exception was never retrieved
future: <Task finished coro=<check_nox() done, defined at D:/MSL_Python/main.py:797> exception=AttributeError("'NoneType' object has no attribute 'send'",)>
Traceback (most recent call last):
  File "D:/MSL_Python/main.py", line 833, in check_nox
    await user.send(f'No PID found for {emu}, restarting Emulator')
AttributeError: 'NoneType' object has no attribute 'send'
CRITICAL 2021-02-28 18:11:48,075 - Restarting Nox - Nox_1
ERROR 2021-02-28 18:11:48,075 - Task exception was never retrieved
future: <Task finished coro=<check_nox() done, defined at D:/MSL_Python/main.py:793> exception=AttributeError("'NoneType' object has no attribute 'send'",)>
Traceback (most recent call last):
  File "D:/MSL_Python/main.py", line 830, in check_nox
    await user.send(f'No PID found for {emu}, restarting Emulator')
AttributeError: 'NoneType' object has no attribute 'send'
ERROR 2021-02-28 18:19:12,001 - Task exception was never retrieved
future: <Task finished coro=<check_nox() done, defined at D:/MSL_Python/main.py:794> exception=AttributeError("'NoneType' object has no attribute 'id'",)>
Traceback (most recent call last):
  File "D:/MSL_Python/main.py", line 801, in check_nox
    userid = discord_get(PEPE.get_all_members(), name='Embershield', discriminator='9127').id
AttributeError: 'NoneType' object has no attribute 'id'
ERROR 2021-02-28 18:19:21,251 - Task exception was never retrieved
future: <Task finished coro=<check_nox() done, defined at D:/MSL_Python/main.py:794> exception=AttributeError("'NoneType' object has no attribute 'id'",)>
Traceback (most recent call last):
  File "D:/MSL_Python/main.py", line 801, in check_nox
    userid = discord_get(PEPE.get_all_members(), name='Embershield', discriminator='9127').id
AttributeError: 'NoneType' object has no attribute 'id'
CRITICAL 2021-02-28 18:19:53,102 - Restarting Nox - Nox_1
ERROR 2021-02-28 18:19:53,102 - Task exception was never retrieved
future: <Task finished coro=<check_nox() done, defined at D:/MSL_Python/main.py:794> exception=AttributeError("'NoneType' object has no attribute 'send'",)>
Traceback (most recent call last):
  File "D:/MSL_Python/main.py", line 833, in check_nox
    await user.send(f'No PID found for {emu}, restarting Emulator')
AttributeError: 'NoneType' object has no attribute 'send'
CRITICAL 2021-02-28 18:36:59,544 - Restarting Nox - Nox_1
ERROR 2021-02-28 18:36:59,544 - Task exception was never retrieved
future: <Task finished coro=<check_nox() done, defined at D:/MSL_Python/main.py:794> exception=AttributeError("'NoneType' object has no attribute 'send'",)>
Traceback (most recent call last):
  File "D:/MSL_Python/main.py", line 833, in check_nox
    await user.send(f'No PID found for {emu}, restarting Emulator')
AttributeError: 'NoneType' object has no attribute 'send'
CRITICAL 2021-02-28 18:38:23,839 - Restarting Nox - Nox_1
ERROR 2021-02-28 18:38:23,839 - Task exception was never retrieved
future: <Task finished coro=<check_nox() done, defined at D:/MSL_Python/main.py:794> exception=AttributeError("'NoneType' object has no attribute 'send'",)>
Traceback (most recent call last):
  File "D:/MSL_Python/main.py", line 832, in check_nox
    await user.send(f'No PID found for {emu}, restarting Emulator')
AttributeError: 'NoneType' object has no attribute 'send'
CRITICAL 2021-02-28 18:46:23,126 - Restarting Nox - Nox_1
ERROR 2021-02-28 18:46:23,126 - Task exception was never retrieved
future: <Task finished coro=<check_nox() done, defined at D:/MSL_Python/main.py:794> exception=AttributeError("'NoneType' object has no attribute 'send'",)>
Traceback (most recent call last):
  File "D:/MSL_Python/main.py", line 832, in check_nox
    await user.send(f'No PID found for {emu}, restarting Emulator')
AttributeError: 'NoneType' object has no attribute 'send'
CRITICAL 2021-02-28 19:11:13,164 - Restarting Nox - Nox_1
CRITICAL 2021-02-28 19:17:02,036 - Restarting Nox - Nox_1
CRITICAL 2021-02-28 19:17:38,639 - Restarting Nox - Nox_1
CRITICAL 2021-02-28 19:47:43,556 - Restarting Nox - Nox_1
ERROR 2021-02-28 19:52:57,959 - Function: save_ping_list, args: ({83: ['<@302905219036086274>']},), kwargs {}, Result: 'AiofilesContextManager' object has no attribute 'write'
ERROR 2021-02-28 19:56:13,676 - Function: save_ping_list, args: ({85: ['<@302905219036086274>']},), kwargs {}, Result: 'AiofilesContextManager' object has no attribute 'write'
ERROR 2021-02-28 19:57:42,249 - Function: save_ping_list, args: ({82: ['<@302905219036086274>']},), kwargs {}, Result: 'AiofilesContextManager' object has no attribute 'write'
ERROR 2021-02-28 19:59:35,246 - Function: save_ping_list, args: ({'82': ['<@302905219036086274>'], 85: ['<@302905219036086274>']},), kwargs {}, Result: '<' not supported between instances of 'int' and 'str'
ERROR 2021-02-28 20:21:07,353 - Task exception was never retrieved
future: <Task finished coro=<check_titan() done, defined at D:/MSL_Python/main.py:733> exception=RuntimeError('ERROR: connecting to 127.0.0.1:5037 [WinError 10061] Es konnte keine Verbindung hergestellt werden, da der Zielcomputer die Verbindung verweigerte.\nIs adb running on your computer?',)>
Traceback (most recent call last):
  File "C:\Program Files\Python36\lib\site-packages\ppadb\connection.py", line 36, in connect
    self.socket.connect((self.host, self.port))
ConnectionRefusedError: [WinError 10061] Es konnte keine Verbindung hergestellt werden, da der Zielcomputer die Verbindung verweigerte

During handling of the above exception, another exception occurred:

Traceback (most recent call last):
  File "D:/MSL_Python/main.py", line 744, in check_titan
    await MAIN.screenshot()
  File "D:/MSL_Python/main.py", line 96, in screenshot
    self.screen = Image.open(io.BytesIO(self.device.screencap()))
  File "C:\Program Files\Python36\lib\site-packages\ppadb\command\transport\__init__.py", line 41, in screencap
    conn = self.create_connection()
  File "C:\Program Files\Python36\lib\site-packages\ppadb\device.py", line 42, in create_connection
    conn = self.client.create_connection(timeout=timeout)
  File "C:\Program Files\Python36\lib\site-packages\ppadb\client.py", line 14, in create_connection
    conn.connect()
  File "C:\Program Files\Python36\lib\site-packages\ppadb\connection.py", line 42, in connect
    e
RuntimeError: ERROR: connecting to 127.0.0.1:5037 [WinError 10061] Es konnte keine Verbindung hergestellt werden, da der Zielcomputer die Verbindung verweigerte.
Is adb running on your computer?
CRITICAL 2021-02-28 20:21:59,853 - Restarting Nox - Nox_0
ERROR 2021-03-03 16:29:37,409 - Function: save_ping_list, args: ({'86': ['<@302905219036086274>'], '87': ['<@302905219036086274>'], '88': ['<@302905219036086274>'], 91: '<@302905219036086274>'},), kwargs {}, Result: '<' not supported between instances of 'int' and 'str'
ERROR 2021-03-03 16:30:19,326 - Function: get_ping_list, args: (), kwargs {}, Result: Expecting property name enclosed in double quotes: line 2 column 5 (char 6)
ERROR 2021-03-03 17:00:09,792 - Function: command_bot, args: (['log', 'stop'], 0), kwargs {}, Result: ControlClick failed
ERROR 2021-03-03 17:00:54,641 - Function: command_bot, args: (['log', 'stop'], 0), kwargs {}, Result: ControlClick failed
ERROR 2021-03-03 17:02:10,832 - Function: command_bot, args: (['log', 'stop'], 0), kwargs {}, Result: ControlClick failed
ERROR 2021-03-03 17:04:31,108 - Function: command_bot, args: (['log', 'stop'], 0), kwargs {}, Result: ControlClick failed
ERROR 2021-03-03 17:05:09,518 - Function: command_bot, args: (['log', 'stop'], 0), kwargs {}, Result: ControlClick failed
ERROR 2021-03-03 17:06:18,124 - Function: command_bot, args: (['log', 'stop'], 0), kwargs {}, Result: ControlClick failed
ERROR 2021-03-03 17:07:01,380 - Function: command_bot, args: (['log', 'stop'], 0), kwargs {}, Result: ControlClick failed
ERROR 2021-03-03 17:07:18,456 - Task exception was never retrieved
future: <Task finished coro=<check_titan() done, defined at D:/MSL_Python/main.py:215> exception=TypeError("'bool' object is not iterable",)>
Traceback (most recent call last):
  File "D:/MSL_Python/main.py", line 217, in call
    result = await func(*args, **kwargs)
  File "D:/MSL_Python/main.py", line 779, in check_titan
    level, element = await titan_level()
TypeError: 'bool' object is not iterable
ERROR 2021-03-03 17:45:34,974 - Task exception was never retrieved
future: <Task finished coro=<check_titan() done, defined at D:/MSL_Python/main.py:215> exception=error("OpenCV(4.0.1) C:\\projects\\opencv-python\\opencv\\modules\\imgproc\\src\\templmatch.cpp:1107: error: (-215:Assertion failed) (depth == CV_8U || depth == CV_32F) && type == _templ.type() && _img.dims() <= 2 in function 'cv::matchTemplate'\n",)>
Traceback (most recent call last):
  File "D:/MSL_Python/main.py", line 217, in call
    result = await func(*args, **kwargs)
  File "D:/MSL_Python/main.py", line 779, in check_titan
    level, element = await titan_level()
  File "D:/MSL_Python/main.py", line 217, in call
    result = await func(*args, **kwargs)
  File "D:/MSL_Python/main.py", line 1050, in titan_level
    result = cv2.matchTemplate(crop_red, tmp, cv2.TM_CCOEFF_NORMED)
cv2.error: OpenCV(4.0.1) C:\projects\opencv-python\opencv\modules\imgproc\src\templmatch.cpp:1107: error: (-215:Assertion failed) (depth == CV_8U || depth == CV_32F) && type == _templ.type() && _img.dims() <= 2 in function 'cv::matchTemplate'

ERROR 2021-03-03 17:47:26,141 - Task exception was never retrieved
future: <Task finished coro=<check_titan() done, defined at D:/MSL_Python/main.py:215> exception=error("OpenCV(4.0.1) C:\\projects\\opencv-python\\opencv\\modules\\imgproc\\src\\templmatch.cpp:1107: error: (-215:Assertion failed) (depth == CV_8U || depth == CV_32F) && type == _templ.type() && _img.dims() <= 2 in function 'cv::matchTemplate'\n",)>
Traceback (most recent call last):
  File "D:/MSL_Python/main.py", line 217, in call
    result = await func(*args, **kwargs)
  File "D:/MSL_Python/main.py", line 779, in check_titan
    level, element = await titan_level()
  File "D:/MSL_Python/main.py", line 217, in call
    result = await func(*args, **kwargs)
  File "D:/MSL_Python/main.py", line 1049, in titan_level
    result = cv2.matchTemplate(crop_red, tmp, cv2.TM_CCOEFF_NORMED)
cv2.error: OpenCV(4.0.1) C:\projects\opencv-python\opencv\modules\imgproc\src\templmatch.cpp:1107: error: (-215:Assertion failed) (depth == CV_8U || depth == CV_32F) && type == _templ.type() && _img.dims() <= 2 in function 'cv::matchTemplate'

ERROR 2021-03-03 17:52:46,742 - Task exception was never retrieved
future: <Task finished coro=<check_titan() done, defined at D:/MSL_Python/main.py:215> exception=error("OpenCV(4.0.1) C:\\projects\\opencv-python\\opencv\\modules\\imgproc\\src\\templmatch.cpp:1107: error: (-215:Assertion failed) (depth == CV_8U || depth == CV_32F) && type == _templ.type() && _img.dims() <= 2 in function 'cv::matchTemplate'\n",)>
Traceback (most recent call last):
  File "D:/MSL_Python/main.py", line 217, in call
    result = await func(*args, **kwargs)
  File "D:/MSL_Python/main.py", line 779, in check_titan
    level, element = await titan_level()
  File "D:/MSL_Python/main.py", line 217, in call
    result = await func(*args, **kwargs)
  File "D:/MSL_Python/main.py", line 1045, in titan_level
    result = cv2.matchTemplate(crop_red, tmp, cv2.TM_CCOEFF_NORMED)
cv2.error: OpenCV(4.0.1) C:\projects\opencv-python\opencv\modules\imgproc\src\templmatch.cpp:1107: error: (-215:Assertion failed) (depth == CV_8U || depth == CV_32F) && type == _templ.type() && _img.dims() <= 2 in function 'cv::matchTemplate'

ERROR 2021-03-03 17:55:36,312 - Task exception was never retrieved
future: <Task finished coro=<check_titan() done, defined at D:/MSL_Python/main.py:215> exception=error("OpenCV(4.0.1) C:\\projects\\opencv-python\\opencv\\modules\\imgproc\\src\\templmatch.cpp:1107: error: (-215:Assertion failed) (depth == CV_8U || depth == CV_32F) && type == _templ.type() && _img.dims() <= 2 in function 'cv::matchTemplate'\n",)>
Traceback (most recent call last):
  File "D:/MSL_Python/main.py", line 217, in call
    result = await func(*args, **kwargs)
  File "D:/MSL_Python/main.py", line 779, in check_titan
    level, element = await titan_level()
  File "D:/MSL_Python/main.py", line 217, in call
    result = await func(*args, **kwargs)
  File "D:/MSL_Python/main.py", line 1044, in titan_level
    result = cv2.matchTemplate(crop_red, tmp, cv2.TM_CCOEFF_NORMED)
cv2.error: OpenCV(4.0.1) C:\projects\opencv-python\opencv\modules\imgproc\src\templmatch.cpp:1107: error: (-215:Assertion failed) (depth == CV_8U || depth == CV_32F) && type == _templ.type() && _img.dims() <= 2 in function 'cv::matchTemplate'

ERROR 2021-03-03 17:56:22,617 - Task exception was never retrieved
future: <Task finished coro=<check_titan() done, defined at D:/MSL_Python/main.py:215> exception=error("OpenCV(4.0.1) C:\\projects\\opencv-python\\opencv\\modules\\imgproc\\src\\templmatch.cpp:1107: error: (-215:Assertion failed) (depth == CV_8U || depth == CV_32F) && type == _templ.type() && _img.dims() <= 2 in function 'cv::matchTemplate'\n",)>
Traceback (most recent call last):
  File "D:/MSL_Python/main.py", line 217, in call
    result = await func(*args, **kwargs)
  File "D:/MSL_Python/main.py", line 779, in check_titan
    level, element = await titan_level()
  File "D:/MSL_Python/main.py", line 217, in call
    result = await func(*args, **kwargs)
  File "D:/MSL_Python/main.py", line 1044, in titan_level
    result = cv2.matchTemplate(crop_red, tmp, cv2.TM_CCOEFF_NORMED)
cv2.error: OpenCV(4.0.1) C:\projects\opencv-python\opencv\modules\imgproc\src\templmatch.cpp:1107: error: (-215:Assertion failed) (depth == CV_8U || depth == CV_32F) && type == _templ.type() && _img.dims() <= 2 in function 'cv::matchTemplate'

ERROR 2021-03-03 17:57:49,677 - Task exception was never retrieved
future: <Task finished coro=<check_titan() done, defined at D:/MSL_Python/main.py:215> exception=error("OpenCV(4.0.1) C:\\projects\\opencv-python\\opencv\\modules\\imgproc\\src\\templmatch.cpp:1107: error: (-215:Assertion failed) (depth == CV_8U || depth == CV_32F) && type == _templ.type() && _img.dims() <= 2 in function 'cv::matchTemplate'\n",)>
Traceback (most recent call last):
  File "D:/MSL_Python/main.py", line 217, in call
    result = await func(*args, **kwargs)
  File "D:/MSL_Python/main.py", line 779, in check_titan
    level, element = await titan_level()
  File "D:/MSL_Python/main.py", line 217, in call
    result = await func(*args, **kwargs)
  File "D:/MSL_Python/main.py", line 1044, in titan_level
    result = cv2.matchTemplate(crop_red, tmp, cv2.TM_CCOEFF_NORMED)
cv2.error: OpenCV(4.0.1) C:\projects\opencv-python\opencv\modules\imgproc\src\templmatch.cpp:1107: error: (-215:Assertion failed) (depth == CV_8U || depth == CV_32F) && type == _templ.type() && _img.dims() <= 2 in function 'cv::matchTemplate'

ERROR 2021-03-03 18:03:48,181 - Task exception was never retrieved
future: <Task finished coro=<check_titan() done, defined at D:/MSL_Python/main.py:215> exception=error("OpenCV(4.0.1) C:\\projects\\opencv-python\\opencv\\modules\\imgproc\\src\\templmatch.cpp:1107: error: (-215:Assertion failed) (depth == CV_8U || depth == CV_32F) && type == _templ.type() && _img.dims() <= 2 in function 'cv::matchTemplate'\n",)>
Traceback (most recent call last):
  File "D:/MSL_Python/main.py", line 217, in call
    result = await func(*args, **kwargs)
  File "D:/MSL_Python/main.py", line 779, in check_titan
    level, element = await titan_level()
  File "D:/MSL_Python/main.py", line 217, in call
    result = await func(*args, **kwargs)
  File "D:/MSL_Python/main.py", line 1045, in titan_level
    result = cv2.matchTemplate(crop_red, tmp, cv2.TM_CCOEFF_NORMED)
cv2.error: OpenCV(4.0.1) C:\projects\opencv-python\opencv\modules\imgproc\src\templmatch.cpp:1107: error: (-215:Assertion failed) (depth == CV_8U || depth == CV_32F) && type == _templ.type() && _img.dims() <= 2 in function 'cv::matchTemplate'

ERROR 2021-03-03 18:08:49,255 - Task exception was never retrieved
future: <Task finished coro=<check_titan() done, defined at D:/MSL_Python/main.py:215> exception=error("OpenCV(4.0.1) C:\\projects\\opencv-python\\opencv\\modules\\imgproc\\src\\templmatch.cpp:1107: error: (-215:Assertion failed) (depth == CV_8U || depth == CV_32F) && type == _templ.type() && _img.dims() <= 2 in function 'cv::matchTemplate'\n",)>
Traceback (most recent call last):
  File "D:/MSL_Python/main.py", line 217, in call
    result = await func(*args, **kwargs)
  File "D:/MSL_Python/main.py", line 779, in check_titan
    level, element = await titan_level()
  File "D:/MSL_Python/main.py", line 217, in call
    result = await func(*args, **kwargs)
  File "D:/MSL_Python/main.py", line 1045, in titan_level
    result = cv2.matchTemplate(crop_red, tmp, cv2.TM_CCOEFF_NORMED)
cv2.error: OpenCV(4.0.1) C:\projects\opencv-python\opencv\modules\imgproc\src\templmatch.cpp:1107: error: (-215:Assertion failed) (depth == CV_8U || depth == CV_32F) && type == _templ.type() && _img.dims() <= 2 in function 'cv::matchTemplate'

ERROR 2021-03-03 18:09:01,983 - Task exception was never retrieved
future: <Task finished coro=<check_titan() done, defined at D:/MSL_Python/main.py:215> exception=error("OpenCV(4.0.1) C:\\projects\\opencv-python\\opencv\\modules\\imgproc\\src\\templmatch.cpp:1107: error: (-215:Assertion failed) (depth == CV_8U || depth == CV_32F) && type == _templ.type() && _img.dims() <= 2 in function 'cv::matchTemplate'\n",)>
Traceback (most recent call last):
  File "D:/MSL_Python/main.py", line 217, in call
    result = await func(*args, **kwargs)
  File "D:/MSL_Python/main.py", line 779, in check_titan
    level, element = await titan_level()
  File "D:/MSL_Python/main.py", line 217, in call
    result = await func(*args, **kwargs)
  File "D:/MSL_Python/main.py", line 1045, in titan_level
    result = cv2.matchTemplate(crop_red, tmp, cv2.TM_CCOEFF_NORMED)
cv2.error: OpenCV(4.0.1) C:\projects\opencv-python\opencv\modules\imgproc\src\templmatch.cpp:1107: error: (-215:Assertion failed) (depth == CV_8U || depth == CV_32F) && type == _templ.type() && _img.dims() <= 2 in function 'cv::matchTemplate'

ERROR 2021-03-03 18:26:07,634 - Function: command_bot, args: (['log', 'stop'], 0), kwargs {}, Result: ControlClick failed
ERROR 2021-03-12 18:20:22,838 - Task exception was never retrieved
future: <Task finished coro=<check_titan() done, defined at D:/MSL_Python/main.py:215> exception=error("OpenCV(4.0.1) C:\\projects\\opencv-python\\opencv\\modules\\imgproc\\src\\color.cpp:181: error: (-215:Assertion failed) !_src.empty() in function 'cv::cvtColor'\n",)>
Traceback (most recent call last):
  File "D:/MSL_Python/main.py", line 217, in call
    result = await func(*args, **kwargs)
  File "D:/MSL_Python/main.py", line 779, in check_titan
    level, element = await titan_level()
  File "D:/MSL_Python/main.py", line 217, in call
    result = await func(*args, **kwargs)
  File "D:/MSL_Python/main.py", line 1019, in titan_level
    hsv = cv2.cvtColor(img, cv2.COLOR_BGR2HSV)
cv2.error: OpenCV(4.0.1) C:\projects\opencv-python\opencv\modules\imgproc\src\color.cpp:181: error: (-215:Assertion failed) !_src.empty() in function 'cv::cvtColor'

ERROR 2021-03-12 18:22:53,086 - Task exception was never retrieved
future: <Task finished coro=<check_titan() done, defined at D:/MSL_Python/main.py:215> exception=error("OpenCV(4.0.1) C:\\projects\\opencv-python\\opencv\\modules\\imgproc\\src\\color.cpp:181: error: (-215:Assertion failed) !_src.empty() in function 'cv::cvtColor'\n",)>
Traceback (most recent call last):
  File "D:/MSL_Python/main.py", line 217, in call
    result = await func(*args, **kwargs)
  File "D:/MSL_Python/main.py", line 779, in check_titan
    level, element = await titan_level()
  File "D:/MSL_Python/main.py", line 217, in call
    result = await func(*args, **kwargs)
  File "D:/MSL_Python/main.py", line 1021, in titan_level
    hsv = cv2.cvtColor(img, cv2.COLOR_BGR2HSV)
cv2.error: OpenCV(4.0.1) C:\projects\opencv-python\opencv\modules\imgproc\src\color.cpp:181: error: (-215:Assertion failed) !_src.empty() in function 'cv::cvtColor'

ERROR 2021-03-12 18:24:14,383 - Task exception was never retrieved
future: <Task finished coro=<check_titan() done, defined at D:/MSL_Python/main.py:215> exception=error("OpenCV(4.0.1) C:\\projects\\opencv-python\\opencv\\modules\\imgproc\\src\\color.cpp:181: error: (-215:Assertion failed) !_src.empty() in function 'cv::cvtColor'\n",)>
Traceback (most recent call last):
  File "D:/MSL_Python/main.py", line 217, in call
    result = await func(*args, **kwargs)
  File "D:/MSL_Python/main.py", line 780, in check_titan
    level, element = await titan_level()
  File "D:/MSL_Python/main.py", line 217, in call
    result = await func(*args, **kwargs)
  File "D:/MSL_Python/main.py", line 1023, in titan_level
    hsv = cv2.cvtColor(img, cv2.COLOR_BGR2HSV)
cv2.error: OpenCV(4.0.1) C:\projects\opencv-python\opencv\modules\imgproc\src\color.cpp:181: error: (-215:Assertion failed) !_src.empty() in function 'cv::cvtColor'

ERROR 2021-03-12 18:25:09,376 - Task exception was never retrieved
future: <Task finished coro=<check_titan() done, defined at D:/MSL_Python/main.py:215> exception=error("OpenCV(4.0.1) C:\\projects\\opencv-python\\opencv\\modules\\imgproc\\src\\color.cpp:181: error: (-215:Assertion failed) !_src.empty() in function 'cv::cvtColor'\n",)>
Traceback (most recent call last):
  File "D:/MSL_Python/main.py", line 217, in call
    result = await func(*args, **kwargs)
  File "D:/MSL_Python/main.py", line 780, in check_titan
    level, element = await titan_level()
  File "D:/MSL_Python/main.py", line 217, in call
    result = await func(*args, **kwargs)
  File "D:/MSL_Python/main.py", line 1023, in titan_level
    hsv = cv2.cvtColor(img, cv2.COLOR_BGR2HSV)
cv2.error: OpenCV(4.0.1) C:\projects\opencv-python\opencv\modules\imgproc\src\color.cpp:181: error: (-215:Assertion failed) !_src.empty() in function 'cv::cvtColor'

ERROR 2021-03-12 18:25:36,405 - Task exception was never retrieved
future: <Task finished coro=<check_titan() done, defined at D:/MSL_Python/main.py:215> exception=error("OpenCV(4.0.1) C:\\projects\\opencv-python\\opencv\\modules\\imgproc\\src\\color.cpp:181: error: (-215:Assertion failed) !_src.empty() in function 'cv::cvtColor'\n",)>
Traceback (most recent call last):
  File "D:/MSL_Python/main.py", line 217, in call
    result = await func(*args, **kwargs)
  File "D:/MSL_Python/main.py", line 780, in check_titan
    level, element = await titan_level()
  File "D:/MSL_Python/main.py", line 217, in call
    result = await func(*args, **kwargs)
  File "D:/MSL_Python/main.py", line 1023, in titan_level
    hsv = cv2.cvtColor(img, cv2.COLOR_BGR2HSV)
cv2.error: OpenCV(4.0.1) C:\projects\opencv-python\opencv\modules\imgproc\src\color.cpp:181: error: (-215:Assertion failed) !_src.empty() in function 'cv::cvtColor'

ERROR 2021-03-12 18:26:00,595 - Task exception was never retrieved
future: <Task finished coro=<check_titan() done, defined at D:/MSL_Python/main.py:215> exception=error("OpenCV(4.0.1) C:\\projects\\opencv-python\\opencv\\modules\\imgproc\\src\\color.cpp:181: error: (-215:Assertion failed) !_src.empty() in function 'cv::cvtColor'\n",)>
Traceback (most recent call last):
  File "D:/MSL_Python/main.py", line 217, in call
    result = await func(*args, **kwargs)
  File "D:/MSL_Python/main.py", line 780, in check_titan
    level, element = await titan_level()
  File "D:/MSL_Python/main.py", line 217, in call
    result = await func(*args, **kwargs)
  File "D:/MSL_Python/main.py", line 1023, in titan_level
    hsv = cv2.cvtColor(img, cv2.COLOR_BGR2HSV)
cv2.error: OpenCV(4.0.1) C:\projects\opencv-python\opencv\modules\imgproc\src\color.cpp:181: error: (-215:Assertion failed) !_src.empty() in function 'cv::cvtColor'

ERROR 2021-03-12 18:27:29,669 - Task exception was never retrieved
future: <Task finished coro=<check_titan() done, defined at D:/MSL_Python/main.py:215> exception=error("OpenCV(4.0.1) C:\\projects\\opencv-python\\opencv\\modules\\imgproc\\src\\color.cpp:181: error: (-215:Assertion failed) !_src.empty() in function 'cv::cvtColor'\n",)>
Traceback (most recent call last):
  File "D:/MSL_Python/main.py", line 217, in call
    result = await func(*args, **kwargs)
  File "D:/MSL_Python/main.py", line 780, in check_titan
    level, element = await titan_level()
  File "D:/MSL_Python/main.py", line 217, in call
    result = await func(*args, **kwargs)
  File "D:/MSL_Python/main.py", line 1024, in titan_level
    hsv = cv2.cvtColor(img, cv2.COLOR_BGR2HSV)
cv2.error: OpenCV(4.0.1) C:\projects\opencv-python\opencv\modules\imgproc\src\color.cpp:181: error: (-215:Assertion failed) !_src.empty() in function 'cv::cvtColor'

ERROR 2021-03-12 18:31:35,393 - Function: command_bot, args: (['log', 'stop'], 0), kwargs {}, Result: ControlClick failed
ERROR 2021-03-12 19:21:47,020 - Function: command_bot, args: (['log', 'stop'], 0), kwargs {}, Result: ControlClick failed
ERROR 2021-03-12 19:23:57,954 - Function: command_bot, args: (['log', 'stop'], 0), kwargs {}, Result: ControlClick failed
ERROR 2021-03-12 19:26:08,801 - Function: command_bot, args: (['log', 'stop'], 0), kwargs {}, Result: ControlClick failed
ERROR 2021-03-12 19:28:20,230 - Function: command_bot, args: (['log', 'stop'], 0), kwargs {}, Result: ControlClick failed
ERROR 2021-03-12 19:30:31,743 - Function: command_bot, args: (['log', 'stop'], 0), kwargs {}, Result: ControlClick failed
ERROR 2021-03-12 19:32:38,018 - Function: command_bot, args: (['log', 'stop'], 0), kwargs {}, Result: ControlClick failed
ERROR 2021-03-31 17:33:21,739 - Task exception was never retrieved
future: <Task finished coro=<check_titan() done, defined at D:/MSL_Python/main.py:215> exception=AttributeError("'str' object has no attribute 'screencap'",)>
Traceback (most recent call last):
  File "D:/MSL_Python/main.py", line 217, in call
    result = await func(*args, **kwargs)
  File "D:/MSL_Python/main.py", line 812, in check_titan
    await navigate()
  File "D:/MSL_Python/main.py", line 217, in call
    result = await func(*args, **kwargs)
  File "D:/MSL_Python/main.py", line 885, in navigate
    await handle.screenshot()
  File "D:/MSL_Python/main.py", line 94, in screenshot
    self.screen = Image.open(io.BytesIO(self.device.screencap()))
AttributeError: 'str' object has no attribute 'screencap'
ERROR 2021-03-31 17:46:11,246 - Task exception was never retrieved
future: <Task finished coro=<check_titan() done, defined at D:/MSL_Python/main.py:215> exception=AttributeError("'str' object has no attribute 'screencap'",)>
Traceback (most recent call last):
  File "D:/MSL_Python/main.py", line 217, in call
    result = await func(*args, **kwargs)
  File "D:/MSL_Python/main.py", line 765, in check_titan
    await SMURF.screenshot()
  File "D:/MSL_Python/main.py", line 94, in screenshot
    self.screen = Image.open(io.BytesIO(self.device.screencap()))
AttributeError: 'str' object has no attribute 'screencap'
ERROR 2021-03-31 18:01:31,060 - Task exception was never retrieved
future: <Task finished coro=<check_titan() done, defined at D:/MSL_Python/main.py:216> exception=AttributeError("'str' object has no attribute 'screencap'",)>
Traceback (most recent call last):
  File "D:/MSL_Python/main.py", line 218, in call
    result = await func(*args, **kwargs)
  File "D:/MSL_Python/main.py", line 815, in check_titan
    await navigate()
  File "D:/MSL_Python/main.py", line 218, in call
    result = await func(*args, **kwargs)
  File "D:/MSL_Python/main.py", line 888, in navigate
    await handle.screenshot()
  File "D:/MSL_Python/main.py", line 94, in screenshot
    self.screen = Image.open(io.BytesIO(self.device.screencap()))
AttributeError: 'str' object has no attribute 'screencap'
ERROR 2021-03-31 18:40:32,594 - Task exception was never retrieved
future: <Task finished coro=<check_nox() done, defined at D:/MSL_Python/main.py:216> exception=FileNotFoundError(2, 'Das System kann die angegebene Datei nicht finden', None, 2, None)>
Traceback (most recent call last):
  File "D:/MSL_Python/main.py", line 218, in call
    result = await func(*args, **kwargs)
  File "D:/MSL_Python/main.py", line 875, in check_nox
    creationflags=DETACHED_PROCESS, close_fds=True)
  File "C:\Program Files\Python36\lib\subprocess.py", line 709, in __init__
    restore_signals, start_new_session)
  File "C:\Program Files\Python36\lib\subprocess.py", line 997, in _execute_child
    startupinfo)
FileNotFoundError: [WinError 2] Das System kann die angegebene Datei nicht finden
ERROR 2021-03-31 20:44:30,470 - Task exception was never retrieved
future: <Task finished coro=<check_titan() done, defined at D:/MSL_Python/main.py:216> exception=AttributeError("'str' object has no attribute 'screencap'",)>
Traceback (most recent call last):
  File "D:/MSL_Python/main.py", line 218, in call
    result = await func(*args, **kwargs)
  File "D:/MSL_Python/main.py", line 815, in check_titan
    await navigate()
  File "D:/MSL_Python/main.py", line 218, in call
    result = await func(*args, **kwargs)
  File "D:/MSL_Python/main.py", line 888, in navigate
    await handle.screenshot()
  File "D:/MSL_Python/main.py", line 94, in screenshot
    self.screen = Image.open(io.BytesIO(self.device.screencap()))
AttributeError: 'str' object has no attribute 'screencap'
ERROR 2021-03-31 22:14:20,742 - Task exception was never retrieved
future: <Task finished coro=<check_titan() done, defined at D:/MSL_Python/main.py:216> exception=AttributeError("'str' object has no attribute 'screencap'",)>
Traceback (most recent call last):
  File "D:/MSL_Python/main.py", line 218, in call
    result = await func(*args, **kwargs)
  File "D:/MSL_Python/main.py", line 815, in check_titan
    await SMURF.screenshot()
  File "D:/MSL_Python/main.py", line 218, in call
    result = await func(*args, **kwargs)
  File "D:/MSL_Python/main.py", line 888, in navigate
    'play', 'skip', 'tap', 'tap2', 'tap3', 'pause', 'give_up', 'give_up2', 'map', 'region_defense',
  File "D:/MSL_Python/main.py", line 94, in screenshot
    self.screen = Image.open(io.BytesIO(self.device.screencap()))
AttributeError: 'str' object has no attribute 'screencap'
ERROR 2021-03-31 23:00:18,647 - Task exception was never retrieved
future: <Task finished coro=<check_titan() done, defined at D:/MSL_Python/main.py:216> exception=AttributeError("'str' object has no attribute 'screencap'",)>
Traceback (most recent call last):
  File "D:/MSL_Python/main.py", line 218, in call
    result = await func(*args, **kwargs)
  File "D:/MSL_Python/main.py", line 764, in check_titan
    await SMURF.screenshot()
  File "D:/MSL_Python/main.py", line 94, in screenshot
    self.screen = Image.open(io.BytesIO(self.device.screencap()))
AttributeError: 'str' object has no attribute 'screencap'
ERROR 2021-04-01 19:37:02,899 - Task exception was never retrieved
future: <Task finished coro=<check_titan() done, defined at D:/MSL_Python/main.py:217> exception=NotFound('404 Not Found (error code: 10008): Unknown Message',)>
Traceback (most recent call last):
  File "D:/MSL_Python/main.py", line 219, in call
    async def call(*args, **kwargs):
  File "D:/MSL_Python/main.py", line 786, in check_titan
    embed.add_field(name='Current HP:', value='*~WIP~*', inline=True)
  File "C:\Program Files\Python36\lib\site-packages\discord\message.py", line 951, in delete
    await self._state.http.delete_message(self.channel.id, self.id)
  File "C:\Program Files\Python36\lib\site-packages\discord\http.py", line 243, in request
    raise NotFound(r, data)
discord.errors.NotFound: 404 Not Found (error code: 10008): Unknown Message
ERROR 2021-04-01 22:48:00,754 - Attempting a reconnect in 1.85s
Traceback (most recent call last):
  File "C:\Program Files\Python36\lib\site-packages\aiohttp\connector.py", line 999, in _create_direct_connection
    hosts = await asyncio.shield(host_resolved)
  File "C:\Program Files\Python36\lib\site-packages\aiohttp\connector.py", line 865, in _resolve_host
    addrs = await self._resolver.resolve(host, port, family=self._family)
  File "C:\Program Files\Python36\lib\site-packages\aiohttp\resolver.py", line 36, in resolve
    flags=socket.AI_ADDRCONFIG,
  File "C:\Program Files\Python36\lib\concurrent\futures\thread.py", line 56, in run
    result = self.fn(*self.args, **self.kwargs)
  File "C:\Program Files\Python36\lib\socket.py", line 745, in getaddrinfo
    for res in _socket.getaddrinfo(host, port, family, type, proto, flags):
socket.gaierror: [Errno 11001] getaddrinfo failed

The above exception was the direct cause of the following exception:

Traceback (most recent call last):
  File "C:\Program Files\Python36\lib\site-packages\discord\client.py", line 558, in connect
    self.ws = await asyncio.wait_for(coro, timeout=60.0)
  File "C:\Program Files\Python36\lib\asyncio\tasks.py", line 358, in wait_for
    return fut.result()
  File "C:\Program Files\Python36\lib\site-packages\discord\gateway.py", line 305, in from_client
    gateway = gateway or await client.http.get_gateway()
  File "C:\Program Files\Python36\lib\site-packages\discord\http.py", line 917, in get_gateway
    data = await self.request(Route('GET', '/gateway'))
  File "C:\Program Files\Python36\lib\site-packages\discord\http.py", line 185, in request
    async with self.__session.request(method, url, **kwargs) as r:
  File "C:\Program Files\Python36\lib\site-packages\aiohttp\client.py", line 1117, in __aenter__
    self._resp = await self._coro
  File "C:\Program Files\Python36\lib\site-packages\aiohttp\client.py", line 521, in _request
    req, traces=traces, timeout=real_timeout
  File "C:\Program Files\Python36\lib\site-packages\aiohttp\connector.py", line 535, in connect
    proto = await self._create_connection(req, traces, timeout)
  File "C:\Program Files\Python36\lib\site-packages\aiohttp\connector.py", line 892, in _create_connection
    _, proto = await self._create_direct_connection(req, traces, timeout)
  File "C:\Program Files\Python36\lib\site-packages\aiohttp\connector.py", line 1011, in _create_direct_connection
    raise ClientConnectorError(req.connection_key, exc) from exc
aiohttp.client_exceptions.ClientConnectorError: Cannot connect to host discord.com:443 ssl:default [getaddrinfo failed]
ERROR 2021-04-01 22:48:02,615 - Attempting a reconnect in 2.03s
Traceback (most recent call last):
  File "C:\Program Files\Python36\lib\site-packages\aiohttp\connector.py", line 999, in _create_direct_connection
    hosts = await asyncio.shield(host_resolved)
  File "C:\Program Files\Python36\lib\site-packages\aiohttp\connector.py", line 865, in _resolve_host
    addrs = await self._resolver.resolve(host, port, family=self._family)
  File "C:\Program Files\Python36\lib\site-packages\aiohttp\resolver.py", line 36, in resolve
    flags=socket.AI_ADDRCONFIG,
  File "C:\Program Files\Python36\lib\concurrent\futures\thread.py", line 56, in run
    result = self.fn(*self.args, **self.kwargs)
  File "C:\Program Files\Python36\lib\socket.py", line 745, in getaddrinfo
    for res in _socket.getaddrinfo(host, port, family, type, proto, flags):
socket.gaierror: [Errno 11004] getaddrinfo failed

The above exception was the direct cause of the following exception:

Traceback (most recent call last):
  File "C:\Program Files\Python36\lib\site-packages\discord\client.py", line 558, in connect
    self.ws = await asyncio.wait_for(coro, timeout=60.0)
  File "C:\Program Files\Python36\lib\asyncio\tasks.py", line 358, in wait_for
    return fut.result()
  File "C:\Program Files\Python36\lib\site-packages\discord\gateway.py", line 305, in from_client
    gateway = gateway or await client.http.get_gateway()
  File "C:\Program Files\Python36\lib\site-packages\discord\http.py", line 917, in get_gateway
    data = await self.request(Route('GET', '/gateway'))
  File "C:\Program Files\Python36\lib\site-packages\discord\http.py", line 185, in request
    async with self.__session.request(method, url, **kwargs) as r:
  File "C:\Program Files\Python36\lib\site-packages\aiohttp\client.py", line 1117, in __aenter__
    self._resp = await self._coro
  File "C:\Program Files\Python36\lib\site-packages\aiohttp\client.py", line 521, in _request
    req, traces=traces, timeout=real_timeout
  File "C:\Program Files\Python36\lib\site-packages\aiohttp\connector.py", line 535, in connect
    proto = await self._create_connection(req, traces, timeout)
  File "C:\Program Files\Python36\lib\site-packages\aiohttp\connector.py", line 892, in _create_connection
    _, proto = await self._create_direct_connection(req, traces, timeout)
  File "C:\Program Files\Python36\lib\site-packages\aiohttp\connector.py", line 1011, in _create_direct_connection
    raise ClientConnectorError(req.connection_key, exc) from exc
aiohttp.client_exceptions.ClientConnectorError: Cannot connect to host discord.com:443 ssl:default [getaddrinfo failed]
ERROR 2021-04-02 01:10:30,167 - Attempting a reconnect in 1.30s
Traceback (most recent call last):
  File "C:\Program Files\Python36\lib\site-packages\aiohttp\connector.py", line 999, in _create_direct_connection
    hosts = await asyncio.shield(host_resolved)
  File "C:\Program Files\Python36\lib\site-packages\aiohttp\connector.py", line 865, in _resolve_host
    addrs = await self._resolver.resolve(host, port, family=self._family)
  File "C:\Program Files\Python36\lib\site-packages\aiohttp\resolver.py", line 36, in resolve
    flags=socket.AI_ADDRCONFIG,
  File "C:\Program Files\Python36\lib\concurrent\futures\thread.py", line 56, in run
    result = self.fn(*self.args, **self.kwargs)
  File "C:\Program Files\Python36\lib\socket.py", line 745, in getaddrinfo
    for res in _socket.getaddrinfo(host, port, family, type, proto, flags):
socket.gaierror: [Errno 11001] getaddrinfo failed

The above exception was the direct cause of the following exception:

Traceback (most recent call last):
  File "C:\Program Files\Python36\lib\site-packages\discord\client.py", line 558, in connect
    self.ws = await asyncio.wait_for(coro, timeout=60.0)
  File "C:\Program Files\Python36\lib\asyncio\tasks.py", line 358, in wait_for
    return fut.result()
  File "C:\Program Files\Python36\lib\site-packages\discord\gateway.py", line 305, in from_client
    gateway = gateway or await client.http.get_gateway()
  File "C:\Program Files\Python36\lib\site-packages\discord\http.py", line 917, in get_gateway
    data = await self.request(Route('GET', '/gateway'))
  File "C:\Program Files\Python36\lib\site-packages\discord\http.py", line 185, in request
    async with self.__session.request(method, url, **kwargs) as r:
  File "C:\Program Files\Python36\lib\site-packages\aiohttp\client.py", line 1117, in __aenter__
    self._resp = await self._coro
  File "C:\Program Files\Python36\lib\site-packages\aiohttp\client.py", line 521, in _request
    req, traces=traces, timeout=real_timeout
  File "C:\Program Files\Python36\lib\site-packages\aiohttp\connector.py", line 535, in connect
    proto = await self._create_connection(req, traces, timeout)
  File "C:\Program Files\Python36\lib\site-packages\aiohttp\connector.py", line 892, in _create_connection
    _, proto = await self._create_direct_connection(req, traces, timeout)
  File "C:\Program Files\Python36\lib\site-packages\aiohttp\connector.py", line 1011, in _create_direct_connection
    raise ClientConnectorError(req.connection_key, exc) from exc
aiohttp.client_exceptions.ClientConnectorError: Cannot connect to host discord.com:443 ssl:default [getaddrinfo failed]
ERROR 2021-04-02 01:10:31,473 - Attempting a reconnect in 1.09s
Traceback (most recent call last):
  File "C:\Program Files\Python36\lib\site-packages\aiohttp\connector.py", line 999, in _create_direct_connection
    hosts = await asyncio.shield(host_resolved)
  File "C:\Program Files\Python36\lib\site-packages\aiohttp\connector.py", line 865, in _resolve_host
    addrs = await self._resolver.resolve(host, port, family=self._family)
  File "C:\Program Files\Python36\lib\site-packages\aiohttp\resolver.py", line 36, in resolve
    flags=socket.AI_ADDRCONFIG,
  File "C:\Program Files\Python36\lib\concurrent\futures\thread.py", line 56, in run
    result = self.fn(*self.args, **self.kwargs)
  File "C:\Program Files\Python36\lib\socket.py", line 745, in getaddrinfo
    for res in _socket.getaddrinfo(host, port, family, type, proto, flags):
socket.gaierror: [Errno 11004] getaddrinfo failed

The above exception was the direct cause of the following exception:

Traceback (most recent call last):
  File "C:\Program Files\Python36\lib\site-packages\discord\client.py", line 558, in connect
    self.ws = await asyncio.wait_for(coro, timeout=60.0)
  File "C:\Program Files\Python36\lib\asyncio\tasks.py", line 358, in wait_for
    return fut.result()
  File "C:\Program Files\Python36\lib\site-packages\discord\gateway.py", line 305, in from_client
    gateway = gateway or await client.http.get_gateway()
  File "C:\Program Files\Python36\lib\site-packages\discord\http.py", line 917, in get_gateway
    data = await self.request(Route('GET', '/gateway'))
  File "C:\Program Files\Python36\lib\site-packages\discord\http.py", line 185, in request
    async with self.__session.request(method, url, **kwargs) as r:
  File "C:\Program Files\Python36\lib\site-packages\aiohttp\client.py", line 1117, in __aenter__
    self._resp = await self._coro
  File "C:\Program Files\Python36\lib\site-packages\aiohttp\client.py", line 521, in _request
    req, traces=traces, timeout=real_timeout
  File "C:\Program Files\Python36\lib\site-packages\aiohttp\connector.py", line 535, in connect
    proto = await self._create_connection(req, traces, timeout)
  File "C:\Program Files\Python36\lib\site-packages\aiohttp\connector.py", line 892, in _create_connection
    _, proto = await self._create_direct_connection(req, traces, timeout)
  File "C:\Program Files\Python36\lib\site-packages\aiohttp\connector.py", line 1011, in _create_direct_connection
    raise ClientConnectorError(req.connection_key, exc) from exc
aiohttp.client_exceptions.ClientConnectorError: Cannot connect to host discord.com:443 ssl:default [getaddrinfo failed]
ERROR 2021-04-02 01:10:32,565 - Attempting a reconnect in 7.02s
Traceback (most recent call last):
  File "C:\Program Files\Python36\lib\site-packages\aiohttp\connector.py", line 999, in _create_direct_connection
    hosts = await asyncio.shield(host_resolved)
  File "C:\Program Files\Python36\lib\site-packages\aiohttp\connector.py", line 865, in _resolve_host
    addrs = await self._resolver.resolve(host, port, family=self._family)
  File "C:\Program Files\Python36\lib\site-packages\aiohttp\resolver.py", line 36, in resolve
    flags=socket.AI_ADDRCONFIG,
  File "C:\Program Files\Python36\lib\concurrent\futures\thread.py", line 56, in run
    result = self.fn(*self.args, **self.kwargs)
  File "C:\Program Files\Python36\lib\socket.py", line 745, in getaddrinfo
    for res in _socket.getaddrinfo(host, port, family, type, proto, flags):
socket.gaierror: [Errno 11004] getaddrinfo failed

The above exception was the direct cause of the following exception:

Traceback (most recent call last):
  File "C:\Program Files\Python36\lib\site-packages\discord\client.py", line 558, in connect
    self.ws = await asyncio.wait_for(coro, timeout=60.0)
  File "C:\Program Files\Python36\lib\asyncio\tasks.py", line 358, in wait_for
    return fut.result()
  File "C:\Program Files\Python36\lib\site-packages\discord\gateway.py", line 305, in from_client
    gateway = gateway or await client.http.get_gateway()
  File "C:\Program Files\Python36\lib\site-packages\discord\http.py", line 917, in get_gateway
    data = await self.request(Route('GET', '/gateway'))
  File "C:\Program Files\Python36\lib\site-packages\discord\http.py", line 185, in request
    async with self.__session.request(method, url, **kwargs) as r:
  File "C:\Program Files\Python36\lib\site-packages\aiohttp\client.py", line 1117, in __aenter__
    self._resp = await self._coro
  File "C:\Program Files\Python36\lib\site-packages\aiohttp\client.py", line 521, in _request
    req, traces=traces, timeout=real_timeout
  File "C:\Program Files\Python36\lib\site-packages\aiohttp\connector.py", line 535, in connect
    proto = await self._create_connection(req, traces, timeout)
  File "C:\Program Files\Python36\lib\site-packages\aiohttp\connector.py", line 892, in _create_connection
    _, proto = await self._create_direct_connection(req, traces, timeout)
  File "C:\Program Files\Python36\lib\site-packages\aiohttp\connector.py", line 1011, in _create_direct_connection
    raise ClientConnectorError(req.connection_key, exc) from exc
aiohttp.client_exceptions.ClientConnectorError: Cannot connect to host discord.com:443 ssl:default [getaddrinfo failed]
ERROR 2021-04-02 01:16:08,156 - _ClientEventTask exception was never retrieved
future: <ClientEventTask state=finished event=on_command_error coro=<bound method Bot.on_command_error of <discord_functions.Bot object at 0x00000145886BCCF8>> exception=TypeError('exceptions must derive from BaseException',)>
Traceback (most recent call last):
  File "C:\Program Files\Python36\lib\site-packages\discord\client.py", line 343, in _run_event
    await coro(*args, **kwargs)
  File "D:\MSL_Python\scripts\logger\__init__.py", line 41, in call
    result = await func(*args, **kwargs)
  File "D:\MSL_Python\scripts\discord_functions\__init__.py", line 59, in on_command_error
    raise exception.original
  File "C:\Program Files\Python36\lib\site-packages\discord\ext\commands\core.py", line 85, in wrapped
    ret = await coro(*args, **kwargs)
  File "D:\MSL_Python\scripts\logger\__init__.py", line 41, in call
    result = await func(*args, **kwargs)
  File "D:\MSL_Python\scripts\cogs\commands.py", line 117, in ss
    image = await save_img(handle.screen, handle.file)
  File "D:\MSL_Python\scripts\logger\__init__.py", line 41, in call
    result = await func(*args, **kwargs)
  File "D:\MSL_Python\scripts\imagetools\__init__.py", line 13, in save_img
    img.save(im_path(output), 'PNG')
AttributeError: 'NoneType' object has no attribute 'save'

During handling of the above exception, another exception occurred:

Traceback (most recent call last):
  File "C:\Program Files\Python36\lib\site-packages\discord\client.py", line 348, in _run_event
    await self.on_error(event_name, *args, **kwargs)
  File "D:\MSL_Python\scripts\logger\__init__.py", line 41, in call
    result = await func(*args, **kwargs)
  File "D:\MSL_Python\scripts\discord_functions\__init__.py", line 52, in on_error
    raise event_method
TypeError: exceptions must derive from BaseException
ERROR 2021-04-02 01:16:15,671 - _ClientEventTask exception was never retrieved
future: <ClientEventTask state=finished event=on_command_error coro=<bound method Bot.on_command_error of <discord_functions.Bot object at 0x00000145886BCCF8>> exception=TypeError('exceptions must derive from BaseException',)>
Traceback (most recent call last):
  File "C:\Program Files\Python36\lib\site-packages\discord\client.py", line 343, in _run_event
    await coro(*args, **kwargs)
  File "D:\MSL_Python\scripts\logger\__init__.py", line 41, in call
    result = await func(*args, **kwargs)
  File "D:\MSL_Python\scripts\discord_functions\__init__.py", line 59, in on_command_error
    raise exception.original
  File "C:\Program Files\Python36\lib\site-packages\discord\ext\commands\core.py", line 85, in wrapped
    ret = await coro(*args, **kwargs)
  File "D:\MSL_Python\scripts\logger\__init__.py", line 41, in call
    result = await func(*args, **kwargs)
  File "D:\MSL_Python\scripts\cogs\commands.py", line 234, in rank
    image = await SMURF.crop_screen('rank', FILE_CFG['RANK'])
  File "D:\MSL_Python\scripts\classes\__init__.py", line 117, in crop_screen
    img_crop = self.screen.crop(area)
AttributeError: 'NoneType' object has no attribute 'crop'

During handling of the above exception, another exception occurred:

Traceback (most recent call last):
  File "C:\Program Files\Python36\lib\site-packages\discord\client.py", line 348, in _run_event
    await self.on_error(event_name, *args, **kwargs)
  File "D:\MSL_Python\scripts\logger\__init__.py", line 41, in call
    result = await func(*args, **kwargs)
  File "D:\MSL_Python\scripts\discord_functions\__init__.py", line 52, in on_error
    raise event_method
TypeError: exceptions must derive from BaseException
ERROR 2021-04-02 01:16:52,152 - _ClientEventTask exception was never retrieved
future: <ClientEventTask state=finished event=on_command_error coro=<bound method Bot.on_command_error of <discord_functions.Bot object at 0x00000239F294CA90>> exception=AttributeError("'NoneType' object has no attribute 'crop'",)>
Traceback (most recent call last):
  File "C:\Program Files\Python36\lib\site-packages\discord\client.py", line 348, in _run_event
    await self.on_error(event_name, *args, **kwargs)
  File "D:\MSL_Python\scripts\logger\__init__.py", line 41, in call
    result = await func(*args, **kwargs)
  File "C:\Program Files\Python36\lib\site-packages\discord\client.py", line 343, in _run_event
    await coro(*args, **kwargs)
  File "D:\MSL_Python\scripts\logger\__init__.py", line 41, in call
    result = await func(*args, **kwargs)
  File "D:\MSL_Python\scripts\discord_functions\__init__.py", line 59, in on_command_error
    raise exception.original
  File "C:\Program Files\Python36\lib\site-packages\discord\ext\commands\core.py", line 85, in wrapped
    ret = await coro(*args, **kwargs)
  File "D:\MSL_Python\scripts\logger\__init__.py", line 41, in call
    result = await func(*args, **kwargs)
  File "D:\MSL_Python\scripts\cogs\commands.py", line 234, in rank
    image = await SMURF.crop_screen('rank', FILE_CFG['RANK'])
  File "D:\MSL_Python\scripts\classes\__init__.py", line 117, in crop_screen
    img_crop = self.screen.crop(area)
AttributeError: 'NoneType' object has no attribute 'crop'
ERROR 2021-04-02 01:19:01,017 - Attempting a reconnect in 1.67s
Traceback (most recent call last):
  File "C:\Program Files\Python36\lib\site-packages\aiohttp\connector.py", line 969, in _wrap_create_connection
    return await self._loop.create_connection(*args, **kwargs)  # type: ignore  # noqa
  File "C:\Program Files\Python36\lib\asyncio\base_events.py", line 783, in create_connection
    raise exceptions[0]
  File "C:\Program Files\Python36\lib\asyncio\base_events.py", line 770, in create_connection
    yield from self.sock_connect(sock, address)
  File "C:\Program Files\Python36\lib\asyncio\selector_events.py", line 450, in sock_connect
    return (yield from fut)
  File "C:\Program Files\Python36\lib\asyncio\selector_events.py", line 480, in _sock_connect_cb
    raise OSError(err, 'Connect call failed %s' % (address,))
OSError: [Errno 10051] Connect call failed ('162.159.136.232', 443)

The above exception was the direct cause of the following exception:

Traceback (most recent call last):
  File "C:\Program Files\Python36\lib\site-packages\discord\client.py", line 558, in connect
    self.ws = await asyncio.wait_for(coro, timeout=60.0)
  File "C:\Program Files\Python36\lib\asyncio\tasks.py", line 358, in wait_for
    return fut.result()
  File "C:\Program Files\Python36\lib\site-packages\discord\gateway.py", line 305, in from_client
    gateway = gateway or await client.http.get_gateway()
  File "C:\Program Files\Python36\lib\site-packages\discord\http.py", line 917, in get_gateway
    data = await self.request(Route('GET', '/gateway'))
  File "C:\Program Files\Python36\lib\site-packages\discord\http.py", line 185, in request
    async with self.__session.request(method, url, **kwargs) as r:
  File "C:\Program Files\Python36\lib\site-packages\aiohttp\client.py", line 1117, in __aenter__
    self._resp = await self._coro
  File "C:\Program Files\Python36\lib\site-packages\aiohttp\client.py", line 521, in _request
    req, traces=traces, timeout=real_timeout
  File "C:\Program Files\Python36\lib\site-packages\aiohttp\connector.py", line 535, in connect
    proto = await self._create_connection(req, traces, timeout)
  File "C:\Program Files\Python36\lib\site-packages\aiohttp\connector.py", line 892, in _create_connection
    _, proto = await self._create_direct_connection(req, traces, timeout)
  File "C:\Program Files\Python36\lib\site-packages\aiohttp\connector.py", line 1051, in _create_direct_connection
    raise last_exc
  File "C:\Program Files\Python36\lib\site-packages\aiohttp\connector.py", line 1032, in _create_direct_connection
    client_error=client_error,
  File "C:\Program Files\Python36\lib\site-packages\aiohttp\connector.py", line 975, in _wrap_create_connection
    raise client_error(req.connection_key, exc) from exc
aiohttp.client_exceptions.ClientConnectorError: Cannot connect to host discord.com:443 ssl:default [Connect call failed ('162.159.136.232', 443)]
ERROR 2021-04-02 01:19:02,695 - Attempting a reconnect in 2.40s
Traceback (most recent call last):
  File "C:\Program Files\Python36\lib\site-packages\aiohttp\connector.py", line 969, in _wrap_create_connection
    return await self._loop.create_connection(*args, **kwargs)  # type: ignore  # noqa
  File "C:\Program Files\Python36\lib\asyncio\base_events.py", line 783, in create_connection
    raise exceptions[0]
  File "C:\Program Files\Python36\lib\asyncio\base_events.py", line 770, in create_connection
    yield from self.sock_connect(sock, address)
  File "C:\Program Files\Python36\lib\asyncio\selector_events.py", line 450, in sock_connect
    return (yield from fut)
  File "C:\Program Files\Python36\lib\asyncio\selector_events.py", line 480, in _sock_connect_cb
    raise OSError(err, 'Connect call failed %s' % (address,))
OSError: [Errno 10051] Connect call failed ('162.159.137.232', 443)

The above exception was the direct cause of the following exception:

Traceback (most recent call last):
  File "C:\Program Files\Python36\lib\site-packages\discord\client.py", line 558, in connect
    self.ws = await asyncio.wait_for(coro, timeout=60.0)
  File "C:\Program Files\Python36\lib\asyncio\tasks.py", line 358, in wait_for
    return fut.result()
  File "C:\Program Files\Python36\lib\site-packages\discord\gateway.py", line 305, in from_client
    gateway = gateway or await client.http.get_gateway()
  File "C:\Program Files\Python36\lib\site-packages\discord\http.py", line 917, in get_gateway
    data = await self.request(Route('GET', '/gateway'))
  File "C:\Program Files\Python36\lib\site-packages\discord\http.py", line 185, in request
    async with self.__session.request(method, url, **kwargs) as r:
  File "C:\Program Files\Python36\lib\site-packages\aiohttp\client.py", line 1117, in __aenter__
    self._resp = await self._coro
  File "C:\Program Files\Python36\lib\site-packages\aiohttp\client.py", line 521, in _request
    req, traces=traces, timeout=real_timeout
  File "C:\Program Files\Python36\lib\site-packages\aiohttp\connector.py", line 535, in connect
    proto = await self._create_connection(req, traces, timeout)
  File "C:\Program Files\Python36\lib\site-packages\aiohttp\connector.py", line 892, in _create_connection
    _, proto = await self._create_direct_connection(req, traces, timeout)
  File "C:\Program Files\Python36\lib\site-packages\aiohttp\connector.py", line 1051, in _create_direct_connection
    raise last_exc
  File "C:\Program Files\Python36\lib\site-packages\aiohttp\connector.py", line 1032, in _create_direct_connection
    client_error=client_error,
  File "C:\Program Files\Python36\lib\site-packages\aiohttp\connector.py", line 975, in _wrap_create_connection
    raise client_error(req.connection_key, exc) from exc
aiohttp.client_exceptions.ClientConnectorError: Cannot connect to host discord.com:443 ssl:default [Connect call failed ('162.159.137.232', 443)]
ERROR 2021-04-03 19:01:35,902 - _ClientEventTask exception was never retrieved
future: <ClientEventTask state=finished event=on_command_error coro=<bound method Bot.on_command_error of <discord_functions.Bot object at 0x000002449234DA58>> exception=TypeError('exceptions must derive from BaseException',)>
Traceback (most recent call last):
  File "C:\Program Files\Python36\lib\site-packages\discord\client.py", line 343, in _run_event
    await coro(*args, **kwargs)
  File "D:\MSL_Python\scripts\logger\__init__.py", line 41, in call
    result = await func(*args, **kwargs)
  File "D:\MSL_Python\scripts\discord_functions\__init__.py", line 60, in on_command_error
    raise exception.original
  File "C:\Program Files\Python36\lib\site-packages\discord\ext\commands\core.py", line 85, in wrapped
    ret = await coro(*args, **kwargs)
  File "D:\MSL_Python\scripts\logger\__init__.py", line 41, in call
    result = await func(*args, **kwargs)
  File "D:\MSL_Python\scripts\cogs\commands.py", line 233, in rank
    image = await g.SMURF.crop_screen('rank', g.FILE_CFG['RANK'])
  File "D:\MSL_Python\scripts\classes\__init__.py", line 116, in crop_screen
    img_crop = self.screen.crop(area)
AttributeError: 'NoneType' object has no attribute 'crop'

During handling of the above exception, another exception occurred:

Traceback (most recent call last):
  File "C:\Program Files\Python36\lib\site-packages\discord\client.py", line 348, in _run_event
    await self.on_error(event_name, *args, **kwargs)
  File "D:\MSL_Python\scripts\logger\__init__.py", line 41, in call
    result = await func(*args, **kwargs)
  File "D:\MSL_Python\scripts\discord_functions\__init__.py", line 53, in on_error
    raise event_method
TypeError: exceptions must derive from BaseException
ERROR 2021-04-03 20:18:52,262 - _ClientEventTask exception was never retrieved
future: <ClientEventTask state=finished event=on_command_error coro=<bound method Bot.on_command_error of <discord_functions.Bot object at 0x000001E3BB123CC0>> exception=TypeError('exceptions must derive from BaseException',)>
Traceback (most recent call last):
  File "C:\Program Files\Python36\lib\site-packages\discord\client.py", line 343, in _run_event
    await coro(*args, **kwargs)
  File "D:\MSL_Python\scripts\logger\__init__.py", line 41, in call
    result = await func(*args, **kwargs)
  File "D:\MSL_Python\scripts\discord_functions\__init__.py", line 63, in on_command_error
    elif isinstance(exception, MissingPermissions):
  File "C:\Program Files\Python36\lib\site-packages\discord\ext\commands\core.py", line 85, in wrapped
    ret = await coro(*args, **kwargs)
  File "D:\MSL_Python\scripts\logger\__init__.py", line 41, in call
    result = await func(*args, **kwargs)
  File "D:\MSL_Python\scripts\cogs\commands.py", line 211, in goto
    going = await navigate(handle)
  File "D:\MSL_Python\scripts\logger\__init__.py", line 41, in call
    result = await func(*args, **kwargs)
  File "D:\MSL_Python\scripts\adbtools\__init__.py", line 141, in navigate
    compare = await compare_image(handle.screen, image)
  File "D:\MSL_Python\scripts\logger\__init__.py", line 41, in call
    result = await func(*args, **kwargs)
  File "D:\MSL_Python\scripts\imagetools\__init__.py", line 30, in compare_image
    template = imread(im_path(tpl))
TypeError: bad argument type for built-in operation

During handling of the above exception, another exception occurred:

Traceback (most recent call last):
  File "C:\Program Files\Python36\lib\site-packages\discord\client.py", line 348, in _run_event
    await self.on_error(event_name, *args, **kwargs)
  File "D:\MSL_Python\scripts\logger\__init__.py", line 41, in call
    result = await func(*args, **kwargs)
  File "D:\MSL_Python\scripts\discord_functions\__init__.py", line 52, in on_error
    kwargs_message = '**kwargs:\n' + '\t'.join(kwargs)
TypeError: exceptions must derive from BaseException
